2025-04-12 18:22:54,721 - root - INFO - Performing risk analysis for MSFT
2025-04-12 18:22:55,015 - yfinance - ERROR - MSFT: No price data found, symbol may be delisted (period=1y)
2025-04-12 18:22:55,017 - yfinance - ERROR - MSFT: No price data found, symbol may be delisted (period=6mo)
2025-04-12 18:22:55,019 - yfinance - ERROR - MSFT: No price data found, symbol may be delisted (period=3mo)
2025-04-12 18:22:55,020 - yfinance - ERROR - MSFT: No price data found, symbol may be delisted (period=1y)
2025-04-12 18:22:55,020 - yfinance - ERROR - MSFT: No price data found, symbol may be delisted (period=1mo)
2025-04-12 18:22:55,021 - root - ERROR - Error in risk analysis model for MSFT: module 'yfinance.shared' has no attribute 'exceptions'
2025-04-12 18:22:55,022 - yfinance - ERROR - MSFT: No price data found, symbol may be delisted (period=6mo)
2025-04-12 18:22:55,023 - root - ERROR - Traceback (most recent call last):
  File "C:\Git_Project\Stock_Flipr\backend\python\risk_analysis.py", line 69, in get_stock_data
    raise ValueError(f"No data found for ticker: {ticker}")
ValueError: No data found for ticker: MSFT

During handling of the above exception, another exception occurred:

Traceback (most recent call last):
  File "C:\Git_Project\Stock_Flipr\backend\python\risk_analysis.py", line 314, in risk_analysis_model
    data = get_stock_data(new_stock_ticker)
           ^^^^^^^^^^^^^^^^^^^^^^^^^^^^^^^^
  File "C:\Git_Project\Stock_Flipr\backend\python\risk_analysis.py", line 73, in get_stock_data
    except yf.shared.exceptions.YFinanceError as yfe:
           ^^^^^^^^^^^^^^^^^^^^
AttributeError: module 'yfinance.shared' has no attribute 'exceptions'

2025-04-12 18:22:55,023 - yfinance - ERROR - MSFT: No price data found, symbol may be delisted (period=3mo)
2025-04-12 18:22:55,025 - yfinance - ERROR - MSFT: No price data found, symbol may be delisted (period=1mo)
2025-04-12 18:22:55,026 - root - ERROR - Error in risk analysis model for MSFT: module 'yfinance.shared' has no attribute 'exceptions'
2025-04-12 18:22:55,027 - root - ERROR - Traceback (most recent call last):
  File "C:\Git_Project\Stock_Flipr\backend\python\risk_analysis.py", line 69, in get_stock_data
    raise ValueError(f"No data found for ticker: {ticker}")
ValueError: No data found for ticker: MSFT

During handling of the above exception, another exception occurred:

Traceback (most recent call last):
  File "C:\Git_Project\Stock_Flipr\backend\python\risk_analysis.py", line 314, in risk_analysis_model
    data = get_stock_data(new_stock_ticker)
           ^^^^^^^^^^^^^^^^^^^^^^^^^^^^^^^^
  File "C:\Git_Project\Stock_Flipr\backend\python\risk_analysis.py", line 73, in get_stock_data
    except yf.shared.exceptions.YFinanceError as yfe:
           ^^^^^^^^^^^^^^^^^^^^
AttributeError: module 'yfinance.shared' has no attribute 'exceptions'

2025-04-12 18:25:57,126 - root - INFO - Performing risk analysis for GOOGL
2025-04-12 18:26:19,653 - root - INFO - Performing risk analysis for GOOGL
2025-04-12 18:26:29,909 - root - INFO - Model for GOOGL trained and saved with accuracy: 0.9018
2025-04-12 18:26:44,553 - root - INFO - Model for GOOGL trained and saved with accuracy: 0.9018
2025-04-12 18:27:41,872 - root - INFO - Performing risk analysis for AMZN
2025-04-12 18:28:07,905 - root - INFO - Model for AMZN trained and saved with accuracy: 0.8655
2025-04-12 18:31:06,118 - root - INFO - Performing risk analysis for AMZN
2025-04-12 18:31:11,316 - root - INFO - Performing risk analysis for AMZN
2025-04-12 18:31:22,367 - root - INFO - Performing risk analysis for AMZN
2025-04-12 18:31:27,029 - root - INFO - Performing risk analysis for AMZN
2025-04-12 18:31:44,786 - root - INFO - Performing risk analysis for TCS.TO
2025-04-12 18:32:05,137 - root - INFO - Model for TCS.TO trained and saved with accuracy: 0.9218
2025-04-12 18:32:44,135 - root - INFO - Performing risk analysis for TCS.TO
2025-04-12 18:32:57,013 - root - INFO - Performing risk analysis for TCS.TO
2025-04-12 18:36:39,789 - root - INFO - Performing risk analysis for TCS.TO
2025-04-12 18:46:03,003 - root - INFO - Performing risk analysis for MSFT
2025-04-12 18:46:21,616 - root - INFO - Performing risk analysis for MSFT
2025-04-12 18:46:22,685 - root - INFO - Model for MSFT trained and saved with accuracy: 0.8655
2025-04-12 18:46:39,802 - root - INFO - Model for MSFT trained and saved with accuracy: 0.8655
2025-04-12 18:47:00,450 - root - INFO - Performing risk analysis for MSFT
2025-04-12 18:47:03,827 - root - INFO - Performing risk analysis for MSFT
2025-04-12 18:49:08,653 - root - INFO - Performing risk analysis for MSFT
2025-04-12 18:49:15,480 - root - INFO - Performing risk analysis for MSFT
2025-04-12 18:55:51,358 - root - INFO - Performing risk analysis for MSFT
2025-04-12 18:55:54,650 - root - INFO - Performing risk analysis for MSFT
2025-04-12 18:56:01,309 - root - INFO - Performing risk analysis for MSFT
2025-04-12 18:56:05,537 - root - INFO - Performing risk analysis for MSFT
2025-04-12 18:56:09,034 - root - INFO - Performing risk analysis for MSFT
2025-04-12 18:56:13,609 - root - INFO - Performing risk analysis for MSFT
2025-04-12 18:56:37,348 - root - INFO - Performing risk analysis for MSFT
2025-04-12 18:56:40,651 - root - INFO - Performing risk analysis for MSFT
2025-04-12 18:56:51,979 - root - INFO - Performing risk analysis for AMZN
2025-04-12 18:57:53,180 - root - INFO - Performing risk analysis for AAPL
2025-04-12 18:58:17,075 - root - INFO - Performing risk analysis for AAPL
2025-04-12 18:58:19,451 - root - INFO - Model for AAPL trained and saved with accuracy: 0.9418
2025-04-12 18:58:29,659 - root - INFO - Performing risk analysis for META
2025-04-12 18:59:03,151 - root - INFO - Model for META trained and saved with accuracy: 0.9418
2025-04-12 19:04:55,510 - root - INFO - Performing risk analysis for META
2025-04-12 19:05:01,666 - root - INFO - Performing risk analysis for META
2025-04-12 19:06:13,840 - root - INFO - Performing risk analysis for META
2025-04-12 19:06:25,706 - root - INFO - Performing risk analysis for META
2025-04-12 19:10:34,193 - root - INFO - Performing risk analysis for AAPL
2025-04-12 19:10:42,058 - root - INFO - Performing risk analysis for AAPL
2025-04-12 19:14:47,462 - root - INFO - Performing risk analysis for AAPL
2025-04-12 19:14:53,947 - root - INFO - Performing risk analysis for AAPL
2025-04-12 19:15:01,576 - root - INFO - Performing risk analysis for AAPL
2025-04-12 19:15:07,366 - root - INFO - Performing risk analysis for AAPL
2025-04-12 19:29:09,516 - root - INFO - Performing risk analysis for AAPL
2025-04-12 19:29:13,335 - root - INFO - Performing risk analysis for AAPL
2025-04-12 19:50:24,870 - root - INFO - Performing risk analysis for AAPL
2025-04-12 19:50:29,460 - root - INFO - Performing risk analysis for AAPL
2025-04-12 19:52:10,053 - root - INFO - Performing risk analysis for AAPL
2025-04-12 19:52:12,707 - root - INFO - Performing risk analysis for AAPL
2025-04-12 19:53:02,311 - root - INFO - Performing risk analysis for AAPL
2025-04-12 19:53:05,742 - root - INFO - Performing risk analysis for AAPL
2025-04-12 19:53:08,462 - root - INFO - Performing risk analysis for AAPL
2025-04-12 19:53:11,102 - root - INFO - Performing risk analysis for AAPL
2025-04-12 19:53:15,860 - root - INFO - Performing risk analysis for AAPL
2025-04-12 19:53:19,339 - root - INFO - Performing risk analysis for AAPL
2025-05-22 22:40:04,964 - root - INFO - Performing risk analysis for AMZN
2025-05-22 22:40:05,600 - root - ERROR - Failed to load model or scaler: node array from the pickle has an incompatible dtype:
- expected: {'names': ['left_child', 'right_child', 'feature', 'threshold', 'impurity', 'n_node_samples', 'weighted_n_node_samples', 'missing_go_to_left'], 'formats': ['<i8', '<i8', '<i8', '<f8', '<f8', '<i8', '<f8', 'u1'], 'offsets': [0, 8, 16, 24, 32, 40, 48, 56], 'itemsize': 64}
- got     : [('left_child', '<i8'), ('right_child', '<i8'), ('feature', '<i8'), ('threshold', '<f8'), ('impurity', '<f8'), ('n_node_samples', '<i8'), ('weighted_n_node_samples', '<f8')]
2025-05-22 22:40:05,601 - root - ERROR - Error in risk analysis model for AMZN: Failed to load model or scaler: node array from the pickle has an incompatible dtype:
- expected: {'names': ['left_child', 'right_child', 'feature', 'threshold', 'impurity', 'n_node_samples', 'weighted_n_node_samples', 'missing_go_to_left'], 'formats': ['<i8', '<i8', '<i8', '<f8', '<f8', '<i8', '<f8', 'u1'], 'offsets': [0, 8, 16, 24, 32, 40, 48, 56], 'itemsize': 64}
- got     : [('left_child', '<i8'), ('right_child', '<i8'), ('feature', '<i8'), ('threshold', '<f8'), ('impurity', '<f8'), ('n_node_samples', '<i8'), ('weighted_n_node_samples', '<f8')]
2025-05-22 22:40:05,602 - root - ERROR - Traceback (most recent call last):
  File "D:\project\Stock_Flipr\backend\python\risk_analysis.py", line 292, in load_model_and_scaler
    model = joblib.load(model_path)
            ^^^^^^^^^^^^^^^^^^^^^^^
  File "C:\Users\Manas\AppData\Roaming\Python\Python311\site-packages\joblib\numpy_pickle.py", line 658, in load
    obj = _unpickle(fobj, filename, mmap_mode)
          ^^^^^^^^^^^^^^^^^^^^^^^^^^^^^^^^^^^^
  File "C:\Users\Manas\AppData\Roaming\Python\Python311\site-packages\joblib\numpy_pickle.py", line 577, in _unpickle
    obj = unpickler.load()
          ^^^^^^^^^^^^^^^^
  File "C:\Program Files\Python311\Lib\pickle.py", line 1213, in load
    dispatch[key[0]](self)
  File "C:\Users\Manas\AppData\Roaming\Python\Python311\site-packages\joblib\numpy_pickle.py", line 402, in load_build
    Unpickler.load_build(self)
  File "C:\Program Files\Python311\Lib\pickle.py", line 1718, in load_build
    setstate(state)
  File "_tree.pyx", line 848, in sklearn.tree._tree.Tree.__setstate__
  File "_tree.pyx", line 1554, in sklearn.tree._tree._check_node_ndarray
ValueError: node array from the pickle has an incompatible dtype:
- expected: {'names': ['left_child', 'right_child', 'feature', 'threshold', 'impurity', 'n_node_samples', 'weighted_n_node_samples', 'missing_go_to_left'], 'formats': ['<i8', '<i8', '<i8', '<f8', '<f8', '<i8', '<f8', 'u1'], 'offsets': [0, 8, 16, 24, 32, 40, 48, 56], 'itemsize': 64}
- got     : [('left_child', '<i8'), ('right_child', '<i8'), ('feature', '<i8'), ('threshold', '<f8'), ('impurity', '<f8'), ('n_node_samples', '<i8'), ('weighted_n_node_samples', '<f8')]

During handling of the above exception, another exception occurred:

Traceback (most recent call last):
  File "D:\project\Stock_Flipr\backend\python\risk_analysis.py", line 333, in risk_analysis_model
    model, scaler, features_used = load_model_and_scaler(model_path, scaler_path)
                                   ^^^^^^^^^^^^^^^^^^^^^^^^^^^^^^^^^^^^^^^^^^^^^^
  File "D:\project\Stock_Flipr\backend\python\risk_analysis.py", line 306, in load_model_and_scaler
    raise ValueError(f"Failed to load model or scaler: {e}")
ValueError: Failed to load model or scaler: node array from the pickle has an incompatible dtype:
- expected: {'names': ['left_child', 'right_child', 'feature', 'threshold', 'impurity', 'n_node_samples', 'weighted_n_node_samples', 'missing_go_to_left'], 'formats': ['<i8', '<i8', '<i8', '<f8', '<f8', '<i8', '<f8', 'u1'], 'offsets': [0, 8, 16, 24, 32, 40, 48, 56], 'itemsize': 64}
- got     : [('left_child', '<i8'), ('right_child', '<i8'), ('feature', '<i8'), ('threshold', '<f8'), ('impurity', '<f8'), ('n_node_samples', '<i8'), ('weighted_n_node_samples', '<f8')]

2025-05-22 22:40:07,745 - root - INFO - Performing risk analysis for AMZN
2025-05-22 22:40:08,197 - root - ERROR - Failed to load model or scaler: node array from the pickle has an incompatible dtype:
- expected: {'names': ['left_child', 'right_child', 'feature', 'threshold', 'impurity', 'n_node_samples', 'weighted_n_node_samples', 'missing_go_to_left'], 'formats': ['<i8', '<i8', '<i8', '<f8', '<f8', '<i8', '<f8', 'u1'], 'offsets': [0, 8, 16, 24, 32, 40, 48, 56], 'itemsize': 64}
- got     : [('left_child', '<i8'), ('right_child', '<i8'), ('feature', '<i8'), ('threshold', '<f8'), ('impurity', '<f8'), ('n_node_samples', '<i8'), ('weighted_n_node_samples', '<f8')]
2025-05-22 22:40:08,197 - root - ERROR - Error in risk analysis model for AMZN: Failed to load model or scaler: node array from the pickle has an incompatible dtype:
- expected: {'names': ['left_child', 'right_child', 'feature', 'threshold', 'impurity', 'n_node_samples', 'weighted_n_node_samples', 'missing_go_to_left'], 'formats': ['<i8', '<i8', '<i8', '<f8', '<f8', '<i8', '<f8', 'u1'], 'offsets': [0, 8, 16, 24, 32, 40, 48, 56], 'itemsize': 64}
- got     : [('left_child', '<i8'), ('right_child', '<i8'), ('feature', '<i8'), ('threshold', '<f8'), ('impurity', '<f8'), ('n_node_samples', '<i8'), ('weighted_n_node_samples', '<f8')]
2025-05-22 22:40:08,199 - root - ERROR - Traceback (most recent call last):
  File "D:\project\Stock_Flipr\backend\python\risk_analysis.py", line 292, in load_model_and_scaler
    model = joblib.load(model_path)
            ^^^^^^^^^^^^^^^^^^^^^^^
  File "C:\Users\Manas\AppData\Roaming\Python\Python311\site-packages\joblib\numpy_pickle.py", line 658, in load
    obj = _unpickle(fobj, filename, mmap_mode)
          ^^^^^^^^^^^^^^^^^^^^^^^^^^^^^^^^^^^^
  File "C:\Users\Manas\AppData\Roaming\Python\Python311\site-packages\joblib\numpy_pickle.py", line 577, in _unpickle
    obj = unpickler.load()
          ^^^^^^^^^^^^^^^^
  File "C:\Program Files\Python311\Lib\pickle.py", line 1213, in load
    dispatch[key[0]](self)
  File "C:\Users\Manas\AppData\Roaming\Python\Python311\site-packages\joblib\numpy_pickle.py", line 402, in load_build
    Unpickler.load_build(self)
  File "C:\Program Files\Python311\Lib\pickle.py", line 1718, in load_build
    setstate(state)
  File "_tree.pyx", line 848, in sklearn.tree._tree.Tree.__setstate__
  File "_tree.pyx", line 1554, in sklearn.tree._tree._check_node_ndarray
ValueError: node array from the pickle has an incompatible dtype:
- expected: {'names': ['left_child', 'right_child', 'feature', 'threshold', 'impurity', 'n_node_samples', 'weighted_n_node_samples', 'missing_go_to_left'], 'formats': ['<i8', '<i8', '<i8', '<f8', '<f8', '<i8', '<f8', 'u1'], 'offsets': [0, 8, 16, 24, 32, 40, 48, 56], 'itemsize': 64}
- got     : [('left_child', '<i8'), ('right_child', '<i8'), ('feature', '<i8'), ('threshold', '<f8'), ('impurity', '<f8'), ('n_node_samples', '<i8'), ('weighted_n_node_samples', '<f8')]

During handling of the above exception, another exception occurred:

Traceback (most recent call last):
  File "D:\project\Stock_Flipr\backend\python\risk_analysis.py", line 333, in risk_analysis_model
    model, scaler, features_used = load_model_and_scaler(model_path, scaler_path)
                                   ^^^^^^^^^^^^^^^^^^^^^^^^^^^^^^^^^^^^^^^^^^^^^^
  File "D:\project\Stock_Flipr\backend\python\risk_analysis.py", line 306, in load_model_and_scaler
    raise ValueError(f"Failed to load model or scaler: {e}")
ValueError: Failed to load model or scaler: node array from the pickle has an incompatible dtype:
- expected: {'names': ['left_child', 'right_child', 'feature', 'threshold', 'impurity', 'n_node_samples', 'weighted_n_node_samples', 'missing_go_to_left'], 'formats': ['<i8', '<i8', '<i8', '<f8', '<f8', '<i8', '<f8', 'u1'], 'offsets': [0, 8, 16, 24, 32, 40, 48, 56], 'itemsize': 64}
- got     : [('left_child', '<i8'), ('right_child', '<i8'), ('feature', '<i8'), ('threshold', '<f8'), ('impurity', '<f8'), ('n_node_samples', '<i8'), ('weighted_n_node_samples', '<f8')]

2025-05-22 22:42:48,522 - root - INFO - Performing risk analysis for ZOMATO.BO
2025-05-22 22:42:58,583 - root - INFO - Model for ZOMATO.BO trained and saved with accuracy: 0.9578
2025-05-22 22:44:08,080 - root - INFO - Performing risk analysis for AMZN
2025-05-22 22:44:08,586 - root - ERROR - Failed to load model or scaler: node array from the pickle has an incompatible dtype:
- expected: {'names': ['left_child', 'right_child', 'feature', 'threshold', 'impurity', 'n_node_samples', 'weighted_n_node_samples', 'missing_go_to_left'], 'formats': ['<i8', '<i8', '<i8', '<f8', '<f8', '<i8', '<f8', 'u1'], 'offsets': [0, 8, 16, 24, 32, 40, 48, 56], 'itemsize': 64}
- got     : [('left_child', '<i8'), ('right_child', '<i8'), ('feature', '<i8'), ('threshold', '<f8'), ('impurity', '<f8'), ('n_node_samples', '<i8'), ('weighted_n_node_samples', '<f8')]
2025-05-22 22:44:08,586 - root - ERROR - Error in risk analysis model for AMZN: Failed to load model or scaler: node array from the pickle has an incompatible dtype:
- expected: {'names': ['left_child', 'right_child', 'feature', 'threshold', 'impurity', 'n_node_samples', 'weighted_n_node_samples', 'missing_go_to_left'], 'formats': ['<i8', '<i8', '<i8', '<f8', '<f8', '<i8', '<f8', 'u1'], 'offsets': [0, 8, 16, 24, 32, 40, 48, 56], 'itemsize': 64}
- got     : [('left_child', '<i8'), ('right_child', '<i8'), ('feature', '<i8'), ('threshold', '<f8'), ('impurity', '<f8'), ('n_node_samples', '<i8'), ('weighted_n_node_samples', '<f8')]
2025-05-22 22:44:08,589 - root - ERROR - Traceback (most recent call last):
  File "D:\project\Stock_Flipr\backend\python\risk_analysis.py", line 292, in load_model_and_scaler
    model = joblib.load(model_path)
            ^^^^^^^^^^^^^^^^^^^^^^^
  File "C:\Users\Manas\AppData\Roaming\Python\Python311\site-packages\joblib\numpy_pickle.py", line 658, in load
    obj = _unpickle(fobj, filename, mmap_mode)
          ^^^^^^^^^^^^^^^^^^^^^^^^^^^^^^^^^^^^
  File "C:\Users\Manas\AppData\Roaming\Python\Python311\site-packages\joblib\numpy_pickle.py", line 577, in _unpickle
    obj = unpickler.load()
          ^^^^^^^^^^^^^^^^
  File "C:\Program Files\Python311\Lib\pickle.py", line 1213, in load
    dispatch[key[0]](self)
  File "C:\Users\Manas\AppData\Roaming\Python\Python311\site-packages\joblib\numpy_pickle.py", line 402, in load_build
    Unpickler.load_build(self)
  File "C:\Program Files\Python311\Lib\pickle.py", line 1718, in load_build
    setstate(state)
  File "_tree.pyx", line 848, in sklearn.tree._tree.Tree.__setstate__
  File "_tree.pyx", line 1554, in sklearn.tree._tree._check_node_ndarray
ValueError: node array from the pickle has an incompatible dtype:
- expected: {'names': ['left_child', 'right_child', 'feature', 'threshold', 'impurity', 'n_node_samples', 'weighted_n_node_samples', 'missing_go_to_left'], 'formats': ['<i8', '<i8', '<i8', '<f8', '<f8', '<i8', '<f8', 'u1'], 'offsets': [0, 8, 16, 24, 32, 40, 48, 56], 'itemsize': 64}
- got     : [('left_child', '<i8'), ('right_child', '<i8'), ('feature', '<i8'), ('threshold', '<f8'), ('impurity', '<f8'), ('n_node_samples', '<i8'), ('weighted_n_node_samples', '<f8')]

During handling of the above exception, another exception occurred:

Traceback (most recent call last):
  File "D:\project\Stock_Flipr\backend\python\risk_analysis.py", line 333, in risk_analysis_model
    model, scaler, features_used = load_model_and_scaler(model_path, scaler_path)
                                   ^^^^^^^^^^^^^^^^^^^^^^^^^^^^^^^^^^^^^^^^^^^^^^
  File "D:\project\Stock_Flipr\backend\python\risk_analysis.py", line 306, in load_model_and_scaler
    raise ValueError(f"Failed to load model or scaler: {e}")
ValueError: Failed to load model or scaler: node array from the pickle has an incompatible dtype:
- expected: {'names': ['left_child', 'right_child', 'feature', 'threshold', 'impurity', 'n_node_samples', 'weighted_n_node_samples', 'missing_go_to_left'], 'formats': ['<i8', '<i8', '<i8', '<f8', '<f8', '<i8', '<f8', 'u1'], 'offsets': [0, 8, 16, 24, 32, 40, 48, 56], 'itemsize': 64}
- got     : [('left_child', '<i8'), ('right_child', '<i8'), ('feature', '<i8'), ('threshold', '<f8'), ('impurity', '<f8'), ('n_node_samples', '<i8'), ('weighted_n_node_samples', '<f8')]

2025-05-22 22:53:03,179 - root - INFO - Performing risk analysis for MSFT
2025-05-22 22:53:03,726 - root - ERROR - Failed to load model or scaler: node array from the pickle has an incompatible dtype:
- expected: {'names': ['left_child', 'right_child', 'feature', 'threshold', 'impurity', 'n_node_samples', 'weighted_n_node_samples', 'missing_go_to_left'], 'formats': ['<i8', '<i8', '<i8', '<f8', '<f8', '<i8', '<f8', 'u1'], 'offsets': [0, 8, 16, 24, 32, 40, 48, 56], 'itemsize': 64}
- got     : [('left_child', '<i8'), ('right_child', '<i8'), ('feature', '<i8'), ('threshold', '<f8'), ('impurity', '<f8'), ('n_node_samples', '<i8'), ('weighted_n_node_samples', '<f8')]
2025-05-22 22:53:03,727 - root - ERROR - Error in risk analysis model for MSFT: Failed to load model or scaler: node array from the pickle has an incompatible dtype:
- expected: {'names': ['left_child', 'right_child', 'feature', 'threshold', 'impurity', 'n_node_samples', 'weighted_n_node_samples', 'missing_go_to_left'], 'formats': ['<i8', '<i8', '<i8', '<f8', '<f8', '<i8', '<f8', 'u1'], 'offsets': [0, 8, 16, 24, 32, 40, 48, 56], 'itemsize': 64}
- got     : [('left_child', '<i8'), ('right_child', '<i8'), ('feature', '<i8'), ('threshold', '<f8'), ('impurity', '<f8'), ('n_node_samples', '<i8'), ('weighted_n_node_samples', '<f8')]
2025-05-22 22:53:03,728 - root - ERROR - Traceback (most recent call last):
  File "D:\project\Stock_Flipr\backend\python\risk_analysis.py", line 292, in load_model_and_scaler
    model = joblib.load(model_path)
            ^^^^^^^^^^^^^^^^^^^^^^^
  File "C:\Users\Manas\AppData\Roaming\Python\Python311\site-packages\joblib\numpy_pickle.py", line 658, in load
    obj = _unpickle(fobj, filename, mmap_mode)
          ^^^^^^^^^^^^^^^^^^^^^^^^^^^^^^^^^^^^
  File "C:\Users\Manas\AppData\Roaming\Python\Python311\site-packages\joblib\numpy_pickle.py", line 577, in _unpickle
    obj = unpickler.load()
          ^^^^^^^^^^^^^^^^
  File "C:\Program Files\Python311\Lib\pickle.py", line 1213, in load
    dispatch[key[0]](self)
  File "C:\Users\Manas\AppData\Roaming\Python\Python311\site-packages\joblib\numpy_pickle.py", line 402, in load_build
    Unpickler.load_build(self)
  File "C:\Program Files\Python311\Lib\pickle.py", line 1718, in load_build
    setstate(state)
  File "_tree.pyx", line 848, in sklearn.tree._tree.Tree.__setstate__
  File "_tree.pyx", line 1554, in sklearn.tree._tree._check_node_ndarray
ValueError: node array from the pickle has an incompatible dtype:
- expected: {'names': ['left_child', 'right_child', 'feature', 'threshold', 'impurity', 'n_node_samples', 'weighted_n_node_samples', 'missing_go_to_left'], 'formats': ['<i8', '<i8', '<i8', '<f8', '<f8', '<i8', '<f8', 'u1'], 'offsets': [0, 8, 16, 24, 32, 40, 48, 56], 'itemsize': 64}
- got     : [('left_child', '<i8'), ('right_child', '<i8'), ('feature', '<i8'), ('threshold', '<f8'), ('impurity', '<f8'), ('n_node_samples', '<i8'), ('weighted_n_node_samples', '<f8')]

During handling of the above exception, another exception occurred:

Traceback (most recent call last):
  File "D:\project\Stock_Flipr\backend\python\risk_analysis.py", line 333, in risk_analysis_model
    model, scaler, features_used = load_model_and_scaler(model_path, scaler_path)
                                   ^^^^^^^^^^^^^^^^^^^^^^^^^^^^^^^^^^^^^^^^^^^^^^
  File "D:\project\Stock_Flipr\backend\python\risk_analysis.py", line 306, in load_model_and_scaler
    raise ValueError(f"Failed to load model or scaler: {e}")
ValueError: Failed to load model or scaler: node array from the pickle has an incompatible dtype:
- expected: {'names': ['left_child', 'right_child', 'feature', 'threshold', 'impurity', 'n_node_samples', 'weighted_n_node_samples', 'missing_go_to_left'], 'formats': ['<i8', '<i8', '<i8', '<f8', '<f8', '<i8', '<f8', 'u1'], 'offsets': [0, 8, 16, 24, 32, 40, 48, 56], 'itemsize': 64}
- got     : [('left_child', '<i8'), ('right_child', '<i8'), ('feature', '<i8'), ('threshold', '<f8'), ('impurity', '<f8'), ('n_node_samples', '<i8'), ('weighted_n_node_samples', '<f8')]

2025-05-22 22:53:05,867 - root - INFO - Performing risk analysis for MSFT
2025-05-22 22:53:06,278 - root - ERROR - Failed to load model or scaler: node array from the pickle has an incompatible dtype:
- expected: {'names': ['left_child', 'right_child', 'feature', 'threshold', 'impurity', 'n_node_samples', 'weighted_n_node_samples', 'missing_go_to_left'], 'formats': ['<i8', '<i8', '<i8', '<f8', '<f8', '<i8', '<f8', 'u1'], 'offsets': [0, 8, 16, 24, 32, 40, 48, 56], 'itemsize': 64}
- got     : [('left_child', '<i8'), ('right_child', '<i8'), ('feature', '<i8'), ('threshold', '<f8'), ('impurity', '<f8'), ('n_node_samples', '<i8'), ('weighted_n_node_samples', '<f8')]
2025-05-22 22:53:06,278 - root - ERROR - Error in risk analysis model for MSFT: Failed to load model or scaler: node array from the pickle has an incompatible dtype:
- expected: {'names': ['left_child', 'right_child', 'feature', 'threshold', 'impurity', 'n_node_samples', 'weighted_n_node_samples', 'missing_go_to_left'], 'formats': ['<i8', '<i8', '<i8', '<f8', '<f8', '<i8', '<f8', 'u1'], 'offsets': [0, 8, 16, 24, 32, 40, 48, 56], 'itemsize': 64}
- got     : [('left_child', '<i8'), ('right_child', '<i8'), ('feature', '<i8'), ('threshold', '<f8'), ('impurity', '<f8'), ('n_node_samples', '<i8'), ('weighted_n_node_samples', '<f8')]
2025-05-22 22:53:06,280 - root - ERROR - Traceback (most recent call last):
  File "D:\project\Stock_Flipr\backend\python\risk_analysis.py", line 292, in load_model_and_scaler
    model = joblib.load(model_path)
            ^^^^^^^^^^^^^^^^^^^^^^^
  File "C:\Users\Manas\AppData\Roaming\Python\Python311\site-packages\joblib\numpy_pickle.py", line 658, in load
    obj = _unpickle(fobj, filename, mmap_mode)
          ^^^^^^^^^^^^^^^^^^^^^^^^^^^^^^^^^^^^
  File "C:\Users\Manas\AppData\Roaming\Python\Python311\site-packages\joblib\numpy_pickle.py", line 577, in _unpickle
    obj = unpickler.load()
          ^^^^^^^^^^^^^^^^
  File "C:\Program Files\Python311\Lib\pickle.py", line 1213, in load
    dispatch[key[0]](self)
  File "C:\Users\Manas\AppData\Roaming\Python\Python311\site-packages\joblib\numpy_pickle.py", line 402, in load_build
    Unpickler.load_build(self)
  File "C:\Program Files\Python311\Lib\pickle.py", line 1718, in load_build
    setstate(state)
  File "_tree.pyx", line 848, in sklearn.tree._tree.Tree.__setstate__
  File "_tree.pyx", line 1554, in sklearn.tree._tree._check_node_ndarray
ValueError: node array from the pickle has an incompatible dtype:
- expected: {'names': ['left_child', 'right_child', 'feature', 'threshold', 'impurity', 'n_node_samples', 'weighted_n_node_samples', 'missing_go_to_left'], 'formats': ['<i8', '<i8', '<i8', '<f8', '<f8', '<i8', '<f8', 'u1'], 'offsets': [0, 8, 16, 24, 32, 40, 48, 56], 'itemsize': 64}
- got     : [('left_child', '<i8'), ('right_child', '<i8'), ('feature', '<i8'), ('threshold', '<f8'), ('impurity', '<f8'), ('n_node_samples', '<i8'), ('weighted_n_node_samples', '<f8')]

During handling of the above exception, another exception occurred:

Traceback (most recent call last):
  File "D:\project\Stock_Flipr\backend\python\risk_analysis.py", line 333, in risk_analysis_model
    model, scaler, features_used = load_model_and_scaler(model_path, scaler_path)
                                   ^^^^^^^^^^^^^^^^^^^^^^^^^^^^^^^^^^^^^^^^^^^^^^
  File "D:\project\Stock_Flipr\backend\python\risk_analysis.py", line 306, in load_model_and_scaler
    raise ValueError(f"Failed to load model or scaler: {e}")
ValueError: Failed to load model or scaler: node array from the pickle has an incompatible dtype:
- expected: {'names': ['left_child', 'right_child', 'feature', 'threshold', 'impurity', 'n_node_samples', 'weighted_n_node_samples', 'missing_go_to_left'], 'formats': ['<i8', '<i8', '<i8', '<f8', '<f8', '<i8', '<f8', 'u1'], 'offsets': [0, 8, 16, 24, 32, 40, 48, 56], 'itemsize': 64}
- got     : [('left_child', '<i8'), ('right_child', '<i8'), ('feature', '<i8'), ('threshold', '<f8'), ('impurity', '<f8'), ('n_node_samples', '<i8'), ('weighted_n_node_samples', '<f8')]

2025-05-23 19:13:42,760 - root - INFO - Performing risk analysis for MSFT
2025-05-23 19:13:45,792 - root - ERROR - Failed to load model or scaler: node array from the pickle has an incompatible dtype:
- expected: {'names': ['left_child', 'right_child', 'feature', 'threshold', 'impurity', 'n_node_samples', 'weighted_n_node_samples', 'missing_go_to_left'], 'formats': ['<i8', '<i8', '<i8', '<f8', '<f8', '<i8', '<f8', 'u1'], 'offsets': [0, 8, 16, 24, 32, 40, 48, 56], 'itemsize': 64}
- got     : [('left_child', '<i8'), ('right_child', '<i8'), ('feature', '<i8'), ('threshold', '<f8'), ('impurity', '<f8'), ('n_node_samples', '<i8'), ('weighted_n_node_samples', '<f8')]
2025-05-23 19:13:45,792 - root - ERROR - Error in risk analysis model for MSFT: Failed to load model or scaler: node array from the pickle has an incompatible dtype:
- expected: {'names': ['left_child', 'right_child', 'feature', 'threshold', 'impurity', 'n_node_samples', 'weighted_n_node_samples', 'missing_go_to_left'], 'formats': ['<i8', '<i8', '<i8', '<f8', '<f8', '<i8', '<f8', 'u1'], 'offsets': [0, 8, 16, 24, 32, 40, 48, 56], 'itemsize': 64}
- got     : [('left_child', '<i8'), ('right_child', '<i8'), ('feature', '<i8'), ('threshold', '<f8'), ('impurity', '<f8'), ('n_node_samples', '<i8'), ('weighted_n_node_samples', '<f8')]
2025-05-23 19:13:45,822 - root - ERROR - Traceback (most recent call last):
  File "D:\project\Stock_Flipr\backend\python\risk_analysis.py", line 292, in load_model_and_scaler
    model = joblib.load(model_path)
            ^^^^^^^^^^^^^^^^^^^^^^^
  File "C:\Users\Manas\AppData\Roaming\Python\Python311\site-packages\joblib\numpy_pickle.py", line 658, in load
    obj = _unpickle(fobj, filename, mmap_mode)
          ^^^^^^^^^^^^^^^^^^^^^^^^^^^^^^^^^^^^
  File "C:\Users\Manas\AppData\Roaming\Python\Python311\site-packages\joblib\numpy_pickle.py", line 577, in _unpickle
    obj = unpickler.load()
          ^^^^^^^^^^^^^^^^
  File "C:\Program Files\Python311\Lib\pickle.py", line 1213, in load
    dispatch[key[0]](self)
  File "C:\Users\Manas\AppData\Roaming\Python\Python311\site-packages\joblib\numpy_pickle.py", line 402, in load_build
    Unpickler.load_build(self)
  File "C:\Program Files\Python311\Lib\pickle.py", line 1718, in load_build
    setstate(state)
  File "_tree.pyx", line 848, in sklearn.tree._tree.Tree.__setstate__
  File "_tree.pyx", line 1554, in sklearn.tree._tree._check_node_ndarray
ValueError: node array from the pickle has an incompatible dtype:
- expected: {'names': ['left_child', 'right_child', 'feature', 'threshold', 'impurity', 'n_node_samples', 'weighted_n_node_samples', 'missing_go_to_left'], 'formats': ['<i8', '<i8', '<i8', '<f8', '<f8', '<i8', '<f8', 'u1'], 'offsets': [0, 8, 16, 24, 32, 40, 48, 56], 'itemsize': 64}
- got     : [('left_child', '<i8'), ('right_child', '<i8'), ('feature', '<i8'), ('threshold', '<f8'), ('impurity', '<f8'), ('n_node_samples', '<i8'), ('weighted_n_node_samples', '<f8')]

During handling of the above exception, another exception occurred:

Traceback (most recent call last):
  File "D:\project\Stock_Flipr\backend\python\risk_analysis.py", line 333, in risk_analysis_model
    model, scaler, features_used = load_model_and_scaler(model_path, scaler_path)
                                   ^^^^^^^^^^^^^^^^^^^^^^^^^^^^^^^^^^^^^^^^^^^^^^
  File "D:\project\Stock_Flipr\backend\python\risk_analysis.py", line 306, in load_model_and_scaler
    raise ValueError(f"Failed to load model or scaler: {e}")
ValueError: Failed to load model or scaler: node array from the pickle has an incompatible dtype:
- expected: {'names': ['left_child', 'right_child', 'feature', 'threshold', 'impurity', 'n_node_samples', 'weighted_n_node_samples', 'missing_go_to_left'], 'formats': ['<i8', '<i8', '<i8', '<f8', '<f8', '<i8', '<f8', 'u1'], 'offsets': [0, 8, 16, 24, 32, 40, 48, 56], 'itemsize': 64}
- got     : [('left_child', '<i8'), ('right_child', '<i8'), ('feature', '<i8'), ('threshold', '<f8'), ('impurity', '<f8'), ('n_node_samples', '<i8'), ('weighted_n_node_samples', '<f8')]

2025-05-23 19:13:48,150 - root - INFO - Performing risk analysis for MSFT
2025-05-23 19:13:48,549 - root - ERROR - Failed to load model or scaler: node array from the pickle has an incompatible dtype:
- expected: {'names': ['left_child', 'right_child', 'feature', 'threshold', 'impurity', 'n_node_samples', 'weighted_n_node_samples', 'missing_go_to_left'], 'formats': ['<i8', '<i8', '<i8', '<f8', '<f8', '<i8', '<f8', 'u1'], 'offsets': [0, 8, 16, 24, 32, 40, 48, 56], 'itemsize': 64}
- got     : [('left_child', '<i8'), ('right_child', '<i8'), ('feature', '<i8'), ('threshold', '<f8'), ('impurity', '<f8'), ('n_node_samples', '<i8'), ('weighted_n_node_samples', '<f8')]
2025-05-23 19:13:48,549 - root - ERROR - Error in risk analysis model for MSFT: Failed to load model or scaler: node array from the pickle has an incompatible dtype:
- expected: {'names': ['left_child', 'right_child', 'feature', 'threshold', 'impurity', 'n_node_samples', 'weighted_n_node_samples', 'missing_go_to_left'], 'formats': ['<i8', '<i8', '<i8', '<f8', '<f8', '<i8', '<f8', 'u1'], 'offsets': [0, 8, 16, 24, 32, 40, 48, 56], 'itemsize': 64}
- got     : [('left_child', '<i8'), ('right_child', '<i8'), ('feature', '<i8'), ('threshold', '<f8'), ('impurity', '<f8'), ('n_node_samples', '<i8'), ('weighted_n_node_samples', '<f8')]
2025-05-23 19:13:48,551 - root - ERROR - Traceback (most recent call last):
  File "D:\project\Stock_Flipr\backend\python\risk_analysis.py", line 292, in load_model_and_scaler
    model = joblib.load(model_path)
            ^^^^^^^^^^^^^^^^^^^^^^^
  File "C:\Users\Manas\AppData\Roaming\Python\Python311\site-packages\joblib\numpy_pickle.py", line 658, in load
    obj = _unpickle(fobj, filename, mmap_mode)
          ^^^^^^^^^^^^^^^^^^^^^^^^^^^^^^^^^^^^
  File "C:\Users\Manas\AppData\Roaming\Python\Python311\site-packages\joblib\numpy_pickle.py", line 577, in _unpickle
    obj = unpickler.load()
          ^^^^^^^^^^^^^^^^
  File "C:\Program Files\Python311\Lib\pickle.py", line 1213, in load
    dispatch[key[0]](self)
  File "C:\Users\Manas\AppData\Roaming\Python\Python311\site-packages\joblib\numpy_pickle.py", line 402, in load_build
    Unpickler.load_build(self)
  File "C:\Program Files\Python311\Lib\pickle.py", line 1718, in load_build
    setstate(state)
  File "_tree.pyx", line 848, in sklearn.tree._tree.Tree.__setstate__
  File "_tree.pyx", line 1554, in sklearn.tree._tree._check_node_ndarray
ValueError: node array from the pickle has an incompatible dtype:
- expected: {'names': ['left_child', 'right_child', 'feature', 'threshold', 'impurity', 'n_node_samples', 'weighted_n_node_samples', 'missing_go_to_left'], 'formats': ['<i8', '<i8', '<i8', '<f8', '<f8', '<i8', '<f8', 'u1'], 'offsets': [0, 8, 16, 24, 32, 40, 48, 56], 'itemsize': 64}
- got     : [('left_child', '<i8'), ('right_child', '<i8'), ('feature', '<i8'), ('threshold', '<f8'), ('impurity', '<f8'), ('n_node_samples', '<i8'), ('weighted_n_node_samples', '<f8')]

During handling of the above exception, another exception occurred:

Traceback (most recent call last):
  File "D:\project\Stock_Flipr\backend\python\risk_analysis.py", line 333, in risk_analysis_model
    model, scaler, features_used = load_model_and_scaler(model_path, scaler_path)
                                   ^^^^^^^^^^^^^^^^^^^^^^^^^^^^^^^^^^^^^^^^^^^^^^
  File "D:\project\Stock_Flipr\backend\python\risk_analysis.py", line 306, in load_model_and_scaler
    raise ValueError(f"Failed to load model or scaler: {e}")
ValueError: Failed to load model or scaler: node array from the pickle has an incompatible dtype:
- expected: {'names': ['left_child', 'right_child', 'feature', 'threshold', 'impurity', 'n_node_samples', 'weighted_n_node_samples', 'missing_go_to_left'], 'formats': ['<i8', '<i8', '<i8', '<f8', '<f8', '<i8', '<f8', 'u1'], 'offsets': [0, 8, 16, 24, 32, 40, 48, 56], 'itemsize': 64}
- got     : [('left_child', '<i8'), ('right_child', '<i8'), ('feature', '<i8'), ('threshold', '<f8'), ('impurity', '<f8'), ('n_node_samples', '<i8'), ('weighted_n_node_samples', '<f8')]

2025-05-23 19:22:31,596 - root - INFO - Performing risk analysis for AAPL
2025-05-23 19:22:34,636 - root - INFO - Performing risk analysis for AAPL
2025-05-23 19:28:38,891 - root - INFO - Performing risk analysis for AAPL
2025-05-23 19:28:41,795 - root - INFO - Performing risk analysis for AAPL
2025-05-23 19:28:56,205 - root - INFO - Performing risk analysis for AAPL
2025-05-23 19:28:59,149 - root - INFO - Performing risk analysis for AAPL
2025-05-23 19:35:24,669 - root - INFO - Performing risk analysis for MSFT
2025-05-23 19:35:26,566 - root - ERROR - Failed to load model or scaler: node array from the pickle has an incompatible dtype:
- expected: {'names': ['left_child', 'right_child', 'feature', 'threshold', 'impurity', 'n_node_samples', 'weighted_n_node_samples', 'missing_go_to_left'], 'formats': ['<i8', '<i8', '<i8', '<f8', '<f8', '<i8', '<f8', 'u1'], 'offsets': [0, 8, 16, 24, 32, 40, 48, 56], 'itemsize': 64}
- got     : [('left_child', '<i8'), ('right_child', '<i8'), ('feature', '<i8'), ('threshold', '<f8'), ('impurity', '<f8'), ('n_node_samples', '<i8'), ('weighted_n_node_samples', '<f8')]
2025-05-23 19:35:26,566 - root - ERROR - Error in risk analysis model for MSFT: Failed to load model or scaler: node array from the pickle has an incompatible dtype:
- expected: {'names': ['left_child', 'right_child', 'feature', 'threshold', 'impurity', 'n_node_samples', 'weighted_n_node_samples', 'missing_go_to_left'], 'formats': ['<i8', '<i8', '<i8', '<f8', '<f8', '<i8', '<f8', 'u1'], 'offsets': [0, 8, 16, 24, 32, 40, 48, 56], 'itemsize': 64}
- got     : [('left_child', '<i8'), ('right_child', '<i8'), ('feature', '<i8'), ('threshold', '<f8'), ('impurity', '<f8'), ('n_node_samples', '<i8'), ('weighted_n_node_samples', '<f8')]
2025-05-23 19:35:26,568 - root - ERROR - Traceback (most recent call last):
  File "D:\project\Stock_Flipr\backend\python\risk_analysis.py", line 292, in load_model_and_scaler
    model = joblib.load(model_path)
            ^^^^^^^^^^^^^^^^^^^^^^^
  File "C:\Users\Manas\AppData\Roaming\Python\Python311\site-packages\joblib\numpy_pickle.py", line 658, in load
    obj = _unpickle(fobj, filename, mmap_mode)
          ^^^^^^^^^^^^^^^^^^^^^^^^^^^^^^^^^^^^
  File "C:\Users\Manas\AppData\Roaming\Python\Python311\site-packages\joblib\numpy_pickle.py", line 577, in _unpickle
    obj = unpickler.load()
          ^^^^^^^^^^^^^^^^
  File "C:\Program Files\Python311\Lib\pickle.py", line 1213, in load
    dispatch[key[0]](self)
  File "C:\Users\Manas\AppData\Roaming\Python\Python311\site-packages\joblib\numpy_pickle.py", line 402, in load_build
    Unpickler.load_build(self)
  File "C:\Program Files\Python311\Lib\pickle.py", line 1718, in load_build
    setstate(state)
  File "_tree.pyx", line 848, in sklearn.tree._tree.Tree.__setstate__
  File "_tree.pyx", line 1554, in sklearn.tree._tree._check_node_ndarray
ValueError: node array from the pickle has an incompatible dtype:
- expected: {'names': ['left_child', 'right_child', 'feature', 'threshold', 'impurity', 'n_node_samples', 'weighted_n_node_samples', 'missing_go_to_left'], 'formats': ['<i8', '<i8', '<i8', '<f8', '<f8', '<i8', '<f8', 'u1'], 'offsets': [0, 8, 16, 24, 32, 40, 48, 56], 'itemsize': 64}
- got     : [('left_child', '<i8'), ('right_child', '<i8'), ('feature', '<i8'), ('threshold', '<f8'), ('impurity', '<f8'), ('n_node_samples', '<i8'), ('weighted_n_node_samples', '<f8')]

During handling of the above exception, another exception occurred:

Traceback (most recent call last):
  File "D:\project\Stock_Flipr\backend\python\risk_analysis.py", line 333, in risk_analysis_model
    model, scaler, features_used = load_model_and_scaler(model_path, scaler_path)
                                   ^^^^^^^^^^^^^^^^^^^^^^^^^^^^^^^^^^^^^^^^^^^^^^
  File "D:\project\Stock_Flipr\backend\python\risk_analysis.py", line 306, in load_model_and_scaler
    raise ValueError(f"Failed to load model or scaler: {e}")
ValueError: Failed to load model or scaler: node array from the pickle has an incompatible dtype:
- expected: {'names': ['left_child', 'right_child', 'feature', 'threshold', 'impurity', 'n_node_samples', 'weighted_n_node_samples', 'missing_go_to_left'], 'formats': ['<i8', '<i8', '<i8', '<f8', '<f8', '<i8', '<f8', 'u1'], 'offsets': [0, 8, 16, 24, 32, 40, 48, 56], 'itemsize': 64}
- got     : [('left_child', '<i8'), ('right_child', '<i8'), ('feature', '<i8'), ('threshold', '<f8'), ('impurity', '<f8'), ('n_node_samples', '<i8'), ('weighted_n_node_samples', '<f8')]

2025-05-23 19:35:28,769 - root - INFO - Performing risk analysis for MSFT
2025-05-23 19:35:30,061 - root - ERROR - Failed to load model or scaler: node array from the pickle has an incompatible dtype:
- expected: {'names': ['left_child', 'right_child', 'feature', 'threshold', 'impurity', 'n_node_samples', 'weighted_n_node_samples', 'missing_go_to_left'], 'formats': ['<i8', '<i8', '<i8', '<f8', '<f8', '<i8', '<f8', 'u1'], 'offsets': [0, 8, 16, 24, 32, 40, 48, 56], 'itemsize': 64}
- got     : [('left_child', '<i8'), ('right_child', '<i8'), ('feature', '<i8'), ('threshold', '<f8'), ('impurity', '<f8'), ('n_node_samples', '<i8'), ('weighted_n_node_samples', '<f8')]
2025-05-23 19:35:30,061 - root - ERROR - Error in risk analysis model for MSFT: Failed to load model or scaler: node array from the pickle has an incompatible dtype:
- expected: {'names': ['left_child', 'right_child', 'feature', 'threshold', 'impurity', 'n_node_samples', 'weighted_n_node_samples', 'missing_go_to_left'], 'formats': ['<i8', '<i8', '<i8', '<f8', '<f8', '<i8', '<f8', 'u1'], 'offsets': [0, 8, 16, 24, 32, 40, 48, 56], 'itemsize': 64}
- got     : [('left_child', '<i8'), ('right_child', '<i8'), ('feature', '<i8'), ('threshold', '<f8'), ('impurity', '<f8'), ('n_node_samples', '<i8'), ('weighted_n_node_samples', '<f8')]
2025-05-23 19:35:30,063 - root - ERROR - Traceback (most recent call last):
  File "D:\project\Stock_Flipr\backend\python\risk_analysis.py", line 292, in load_model_and_scaler
    model = joblib.load(model_path)
            ^^^^^^^^^^^^^^^^^^^^^^^
  File "C:\Users\Manas\AppData\Roaming\Python\Python311\site-packages\joblib\numpy_pickle.py", line 658, in load
    obj = _unpickle(fobj, filename, mmap_mode)
          ^^^^^^^^^^^^^^^^^^^^^^^^^^^^^^^^^^^^
  File "C:\Users\Manas\AppData\Roaming\Python\Python311\site-packages\joblib\numpy_pickle.py", line 577, in _unpickle
    obj = unpickler.load()
          ^^^^^^^^^^^^^^^^
  File "C:\Program Files\Python311\Lib\pickle.py", line 1213, in load
    dispatch[key[0]](self)
  File "C:\Users\Manas\AppData\Roaming\Python\Python311\site-packages\joblib\numpy_pickle.py", line 402, in load_build
    Unpickler.load_build(self)
  File "C:\Program Files\Python311\Lib\pickle.py", line 1718, in load_build
    setstate(state)
  File "_tree.pyx", line 848, in sklearn.tree._tree.Tree.__setstate__
  File "_tree.pyx", line 1554, in sklearn.tree._tree._check_node_ndarray
ValueError: node array from the pickle has an incompatible dtype:
- expected: {'names': ['left_child', 'right_child', 'feature', 'threshold', 'impurity', 'n_node_samples', 'weighted_n_node_samples', 'missing_go_to_left'], 'formats': ['<i8', '<i8', '<i8', '<f8', '<f8', '<i8', '<f8', 'u1'], 'offsets': [0, 8, 16, 24, 32, 40, 48, 56], 'itemsize': 64}
- got     : [('left_child', '<i8'), ('right_child', '<i8'), ('feature', '<i8'), ('threshold', '<f8'), ('impurity', '<f8'), ('n_node_samples', '<i8'), ('weighted_n_node_samples', '<f8')]

During handling of the above exception, another exception occurred:

Traceback (most recent call last):
  File "D:\project\Stock_Flipr\backend\python\risk_analysis.py", line 333, in risk_analysis_model
    model, scaler, features_used = load_model_and_scaler(model_path, scaler_path)
                                   ^^^^^^^^^^^^^^^^^^^^^^^^^^^^^^^^^^^^^^^^^^^^^^
  File "D:\project\Stock_Flipr\backend\python\risk_analysis.py", line 306, in load_model_and_scaler
    raise ValueError(f"Failed to load model or scaler: {e}")
ValueError: Failed to load model or scaler: node array from the pickle has an incompatible dtype:
- expected: {'names': ['left_child', 'right_child', 'feature', 'threshold', 'impurity', 'n_node_samples', 'weighted_n_node_samples', 'missing_go_to_left'], 'formats': ['<i8', '<i8', '<i8', '<f8', '<f8', '<i8', '<f8', 'u1'], 'offsets': [0, 8, 16, 24, 32, 40, 48, 56], 'itemsize': 64}
- got     : [('left_child', '<i8'), ('right_child', '<i8'), ('feature', '<i8'), ('threshold', '<f8'), ('impurity', '<f8'), ('n_node_samples', '<i8'), ('weighted_n_node_samples', '<f8')]

2025-05-23 19:35:52,647 - root - INFO - Performing risk analysis for MSFT
2025-05-23 19:35:53,841 - root - ERROR - Failed to load model or scaler: node array from the pickle has an incompatible dtype:
- expected: {'names': ['left_child', 'right_child', 'feature', 'threshold', 'impurity', 'n_node_samples', 'weighted_n_node_samples', 'missing_go_to_left'], 'formats': ['<i8', '<i8', '<i8', '<f8', '<f8', '<i8', '<f8', 'u1'], 'offsets': [0, 8, 16, 24, 32, 40, 48, 56], 'itemsize': 64}
- got     : [('left_child', '<i8'), ('right_child', '<i8'), ('feature', '<i8'), ('threshold', '<f8'), ('impurity', '<f8'), ('n_node_samples', '<i8'), ('weighted_n_node_samples', '<f8')]
2025-05-23 19:35:53,842 - root - ERROR - Error in risk analysis model for MSFT: Failed to load model or scaler: node array from the pickle has an incompatible dtype:
- expected: {'names': ['left_child', 'right_child', 'feature', 'threshold', 'impurity', 'n_node_samples', 'weighted_n_node_samples', 'missing_go_to_left'], 'formats': ['<i8', '<i8', '<i8', '<f8', '<f8', '<i8', '<f8', 'u1'], 'offsets': [0, 8, 16, 24, 32, 40, 48, 56], 'itemsize': 64}
- got     : [('left_child', '<i8'), ('right_child', '<i8'), ('feature', '<i8'), ('threshold', '<f8'), ('impurity', '<f8'), ('n_node_samples', '<i8'), ('weighted_n_node_samples', '<f8')]
2025-05-23 19:35:53,847 - root - ERROR - Traceback (most recent call last):
  File "D:\project\Stock_Flipr\backend\python\risk_analysis.py", line 292, in load_model_and_scaler
    model = joblib.load(model_path)
            ^^^^^^^^^^^^^^^^^^^^^^^
  File "C:\Users\Manas\AppData\Roaming\Python\Python311\site-packages\joblib\numpy_pickle.py", line 658, in load
    obj = _unpickle(fobj, filename, mmap_mode)
          ^^^^^^^^^^^^^^^^^^^^^^^^^^^^^^^^^^^^
  File "C:\Users\Manas\AppData\Roaming\Python\Python311\site-packages\joblib\numpy_pickle.py", line 577, in _unpickle
    obj = unpickler.load()
          ^^^^^^^^^^^^^^^^
  File "C:\Program Files\Python311\Lib\pickle.py", line 1213, in load
    dispatch[key[0]](self)
  File "C:\Users\Manas\AppData\Roaming\Python\Python311\site-packages\joblib\numpy_pickle.py", line 402, in load_build
    Unpickler.load_build(self)
  File "C:\Program Files\Python311\Lib\pickle.py", line 1718, in load_build
    setstate(state)
  File "_tree.pyx", line 848, in sklearn.tree._tree.Tree.__setstate__
  File "_tree.pyx", line 1554, in sklearn.tree._tree._check_node_ndarray
ValueError: node array from the pickle has an incompatible dtype:
- expected: {'names': ['left_child', 'right_child', 'feature', 'threshold', 'impurity', 'n_node_samples', 'weighted_n_node_samples', 'missing_go_to_left'], 'formats': ['<i8', '<i8', '<i8', '<f8', '<f8', '<i8', '<f8', 'u1'], 'offsets': [0, 8, 16, 24, 32, 40, 48, 56], 'itemsize': 64}
- got     : [('left_child', '<i8'), ('right_child', '<i8'), ('feature', '<i8'), ('threshold', '<f8'), ('impurity', '<f8'), ('n_node_samples', '<i8'), ('weighted_n_node_samples', '<f8')]

During handling of the above exception, another exception occurred:

Traceback (most recent call last):
  File "D:\project\Stock_Flipr\backend\python\risk_analysis.py", line 333, in risk_analysis_model
    model, scaler, features_used = load_model_and_scaler(model_path, scaler_path)
                                   ^^^^^^^^^^^^^^^^^^^^^^^^^^^^^^^^^^^^^^^^^^^^^^
  File "D:\project\Stock_Flipr\backend\python\risk_analysis.py", line 306, in load_model_and_scaler
    raise ValueError(f"Failed to load model or scaler: {e}")
ValueError: Failed to load model or scaler: node array from the pickle has an incompatible dtype:
- expected: {'names': ['left_child', 'right_child', 'feature', 'threshold', 'impurity', 'n_node_samples', 'weighted_n_node_samples', 'missing_go_to_left'], 'formats': ['<i8', '<i8', '<i8', '<f8', '<f8', '<i8', '<f8', 'u1'], 'offsets': [0, 8, 16, 24, 32, 40, 48, 56], 'itemsize': 64}
- got     : [('left_child', '<i8'), ('right_child', '<i8'), ('feature', '<i8'), ('threshold', '<f8'), ('impurity', '<f8'), ('n_node_samples', '<i8'), ('weighted_n_node_samples', '<f8')]

2025-05-23 19:35:56,363 - root - INFO - Performing risk analysis for MSFT
2025-05-23 19:35:57,450 - root - ERROR - Failed to load model or scaler: node array from the pickle has an incompatible dtype:
- expected: {'names': ['left_child', 'right_child', 'feature', 'threshold', 'impurity', 'n_node_samples', 'weighted_n_node_samples', 'missing_go_to_left'], 'formats': ['<i8', '<i8', '<i8', '<f8', '<f8', '<i8', '<f8', 'u1'], 'offsets': [0, 8, 16, 24, 32, 40, 48, 56], 'itemsize': 64}
- got     : [('left_child', '<i8'), ('right_child', '<i8'), ('feature', '<i8'), ('threshold', '<f8'), ('impurity', '<f8'), ('n_node_samples', '<i8'), ('weighted_n_node_samples', '<f8')]
2025-05-23 19:35:57,450 - root - ERROR - Error in risk analysis model for MSFT: Failed to load model or scaler: node array from the pickle has an incompatible dtype:
- expected: {'names': ['left_child', 'right_child', 'feature', 'threshold', 'impurity', 'n_node_samples', 'weighted_n_node_samples', 'missing_go_to_left'], 'formats': ['<i8', '<i8', '<i8', '<f8', '<f8', '<i8', '<f8', 'u1'], 'offsets': [0, 8, 16, 24, 32, 40, 48, 56], 'itemsize': 64}
- got     : [('left_child', '<i8'), ('right_child', '<i8'), ('feature', '<i8'), ('threshold', '<f8'), ('impurity', '<f8'), ('n_node_samples', '<i8'), ('weighted_n_node_samples', '<f8')]
2025-05-23 19:35:57,451 - root - ERROR - Traceback (most recent call last):
  File "D:\project\Stock_Flipr\backend\python\risk_analysis.py", line 292, in load_model_and_scaler
    model = joblib.load(model_path)
            ^^^^^^^^^^^^^^^^^^^^^^^
  File "C:\Users\Manas\AppData\Roaming\Python\Python311\site-packages\joblib\numpy_pickle.py", line 658, in load
    obj = _unpickle(fobj, filename, mmap_mode)
          ^^^^^^^^^^^^^^^^^^^^^^^^^^^^^^^^^^^^
  File "C:\Users\Manas\AppData\Roaming\Python\Python311\site-packages\joblib\numpy_pickle.py", line 577, in _unpickle
    obj = unpickler.load()
          ^^^^^^^^^^^^^^^^
  File "C:\Program Files\Python311\Lib\pickle.py", line 1213, in load
    dispatch[key[0]](self)
  File "C:\Users\Manas\AppData\Roaming\Python\Python311\site-packages\joblib\numpy_pickle.py", line 402, in load_build
    Unpickler.load_build(self)
  File "C:\Program Files\Python311\Lib\pickle.py", line 1718, in load_build
    setstate(state)
  File "_tree.pyx", line 848, in sklearn.tree._tree.Tree.__setstate__
  File "_tree.pyx", line 1554, in sklearn.tree._tree._check_node_ndarray
ValueError: node array from the pickle has an incompatible dtype:
- expected: {'names': ['left_child', 'right_child', 'feature', 'threshold', 'impurity', 'n_node_samples', 'weighted_n_node_samples', 'missing_go_to_left'], 'formats': ['<i8', '<i8', '<i8', '<f8', '<f8', '<i8', '<f8', 'u1'], 'offsets': [0, 8, 16, 24, 32, 40, 48, 56], 'itemsize': 64}
- got     : [('left_child', '<i8'), ('right_child', '<i8'), ('feature', '<i8'), ('threshold', '<f8'), ('impurity', '<f8'), ('n_node_samples', '<i8'), ('weighted_n_node_samples', '<f8')]

During handling of the above exception, another exception occurred:

Traceback (most recent call last):
  File "D:\project\Stock_Flipr\backend\python\risk_analysis.py", line 333, in risk_analysis_model
    model, scaler, features_used = load_model_and_scaler(model_path, scaler_path)
                                   ^^^^^^^^^^^^^^^^^^^^^^^^^^^^^^^^^^^^^^^^^^^^^^
  File "D:\project\Stock_Flipr\backend\python\risk_analysis.py", line 306, in load_model_and_scaler
    raise ValueError(f"Failed to load model or scaler: {e}")
ValueError: Failed to load model or scaler: node array from the pickle has an incompatible dtype:
- expected: {'names': ['left_child', 'right_child', 'feature', 'threshold', 'impurity', 'n_node_samples', 'weighted_n_node_samples', 'missing_go_to_left'], 'formats': ['<i8', '<i8', '<i8', '<f8', '<f8', '<i8', '<f8', 'u1'], 'offsets': [0, 8, 16, 24, 32, 40, 48, 56], 'itemsize': 64}
- got     : [('left_child', '<i8'), ('right_child', '<i8'), ('feature', '<i8'), ('threshold', '<f8'), ('impurity', '<f8'), ('n_node_samples', '<i8'), ('weighted_n_node_samples', '<f8')]

2025-05-23 19:38:10,481 - root - INFO - Performing risk analysis for AAPL
2025-05-23 19:38:14,134 - root - INFO - Performing risk analysis for AAPL
2025-05-23 19:38:23,108 - root - INFO - Performing risk analysis for META
2025-05-23 19:38:24,326 - root - ERROR - Failed to load model or scaler: node array from the pickle has an incompatible dtype:
- expected: {'names': ['left_child', 'right_child', 'feature', 'threshold', 'impurity', 'n_node_samples', 'weighted_n_node_samples', 'missing_go_to_left'], 'formats': ['<i8', '<i8', '<i8', '<f8', '<f8', '<i8', '<f8', 'u1'], 'offsets': [0, 8, 16, 24, 32, 40, 48, 56], 'itemsize': 64}
- got     : [('left_child', '<i8'), ('right_child', '<i8'), ('feature', '<i8'), ('threshold', '<f8'), ('impurity', '<f8'), ('n_node_samples', '<i8'), ('weighted_n_node_samples', '<f8')]
2025-05-23 19:38:24,327 - root - ERROR - Error in risk analysis model for META: Failed to load model or scaler: node array from the pickle has an incompatible dtype:
- expected: {'names': ['left_child', 'right_child', 'feature', 'threshold', 'impurity', 'n_node_samples', 'weighted_n_node_samples', 'missing_go_to_left'], 'formats': ['<i8', '<i8', '<i8', '<f8', '<f8', '<i8', '<f8', 'u1'], 'offsets': [0, 8, 16, 24, 32, 40, 48, 56], 'itemsize': 64}
- got     : [('left_child', '<i8'), ('right_child', '<i8'), ('feature', '<i8'), ('threshold', '<f8'), ('impurity', '<f8'), ('n_node_samples', '<i8'), ('weighted_n_node_samples', '<f8')]
2025-05-23 19:38:24,329 - root - ERROR - Traceback (most recent call last):
  File "D:\project\Stock_Flipr\backend\python\risk_analysis.py", line 292, in load_model_and_scaler
    model = joblib.load(model_path)
            ^^^^^^^^^^^^^^^^^^^^^^^
  File "C:\Users\Manas\AppData\Roaming\Python\Python311\site-packages\joblib\numpy_pickle.py", line 658, in load
    obj = _unpickle(fobj, filename, mmap_mode)
          ^^^^^^^^^^^^^^^^^^^^^^^^^^^^^^^^^^^^
  File "C:\Users\Manas\AppData\Roaming\Python\Python311\site-packages\joblib\numpy_pickle.py", line 577, in _unpickle
    obj = unpickler.load()
          ^^^^^^^^^^^^^^^^
  File "C:\Program Files\Python311\Lib\pickle.py", line 1213, in load
    dispatch[key[0]](self)
  File "C:\Users\Manas\AppData\Roaming\Python\Python311\site-packages\joblib\numpy_pickle.py", line 402, in load_build
    Unpickler.load_build(self)
  File "C:\Program Files\Python311\Lib\pickle.py", line 1718, in load_build
    setstate(state)
  File "_tree.pyx", line 848, in sklearn.tree._tree.Tree.__setstate__
  File "_tree.pyx", line 1554, in sklearn.tree._tree._check_node_ndarray
ValueError: node array from the pickle has an incompatible dtype:
- expected: {'names': ['left_child', 'right_child', 'feature', 'threshold', 'impurity', 'n_node_samples', 'weighted_n_node_samples', 'missing_go_to_left'], 'formats': ['<i8', '<i8', '<i8', '<f8', '<f8', '<i8', '<f8', 'u1'], 'offsets': [0, 8, 16, 24, 32, 40, 48, 56], 'itemsize': 64}
- got     : [('left_child', '<i8'), ('right_child', '<i8'), ('feature', '<i8'), ('threshold', '<f8'), ('impurity', '<f8'), ('n_node_samples', '<i8'), ('weighted_n_node_samples', '<f8')]

During handling of the above exception, another exception occurred:

Traceback (most recent call last):
  File "D:\project\Stock_Flipr\backend\python\risk_analysis.py", line 333, in risk_analysis_model
    model, scaler, features_used = load_model_and_scaler(model_path, scaler_path)
                                   ^^^^^^^^^^^^^^^^^^^^^^^^^^^^^^^^^^^^^^^^^^^^^^
  File "D:\project\Stock_Flipr\backend\python\risk_analysis.py", line 306, in load_model_and_scaler
    raise ValueError(f"Failed to load model or scaler: {e}")
ValueError: Failed to load model or scaler: node array from the pickle has an incompatible dtype:
- expected: {'names': ['left_child', 'right_child', 'feature', 'threshold', 'impurity', 'n_node_samples', 'weighted_n_node_samples', 'missing_go_to_left'], 'formats': ['<i8', '<i8', '<i8', '<f8', '<f8', '<i8', '<f8', 'u1'], 'offsets': [0, 8, 16, 24, 32, 40, 48, 56], 'itemsize': 64}
- got     : [('left_child', '<i8'), ('right_child', '<i8'), ('feature', '<i8'), ('threshold', '<f8'), ('impurity', '<f8'), ('n_node_samples', '<i8'), ('weighted_n_node_samples', '<f8')]

2025-05-23 19:38:32,426 - root - INFO - Performing risk analysis for GOOGL
2025-05-23 19:38:33,306 - root - ERROR - Failed to load model or scaler: node array from the pickle has an incompatible dtype:
- expected: {'names': ['left_child', 'right_child', 'feature', 'threshold', 'impurity', 'n_node_samples', 'weighted_n_node_samples', 'missing_go_to_left'], 'formats': ['<i8', '<i8', '<i8', '<f8', '<f8', '<i8', '<f8', 'u1'], 'offsets': [0, 8, 16, 24, 32, 40, 48, 56], 'itemsize': 64}
- got     : [('left_child', '<i8'), ('right_child', '<i8'), ('feature', '<i8'), ('threshold', '<f8'), ('impurity', '<f8'), ('n_node_samples', '<i8'), ('weighted_n_node_samples', '<f8')]
2025-05-23 19:38:33,307 - root - ERROR - Error in risk analysis model for GOOGL: Failed to load model or scaler: node array from the pickle has an incompatible dtype:
- expected: {'names': ['left_child', 'right_child', 'feature', 'threshold', 'impurity', 'n_node_samples', 'weighted_n_node_samples', 'missing_go_to_left'], 'formats': ['<i8', '<i8', '<i8', '<f8', '<f8', '<i8', '<f8', 'u1'], 'offsets': [0, 8, 16, 24, 32, 40, 48, 56], 'itemsize': 64}
- got     : [('left_child', '<i8'), ('right_child', '<i8'), ('feature', '<i8'), ('threshold', '<f8'), ('impurity', '<f8'), ('n_node_samples', '<i8'), ('weighted_n_node_samples', '<f8')]
2025-05-23 19:38:33,308 - root - ERROR - Traceback (most recent call last):
  File "D:\project\Stock_Flipr\backend\python\risk_analysis.py", line 292, in load_model_and_scaler
    model = joblib.load(model_path)
            ^^^^^^^^^^^^^^^^^^^^^^^
  File "C:\Users\Manas\AppData\Roaming\Python\Python311\site-packages\joblib\numpy_pickle.py", line 658, in load
    obj = _unpickle(fobj, filename, mmap_mode)
          ^^^^^^^^^^^^^^^^^^^^^^^^^^^^^^^^^^^^
  File "C:\Users\Manas\AppData\Roaming\Python\Python311\site-packages\joblib\numpy_pickle.py", line 577, in _unpickle
    obj = unpickler.load()
          ^^^^^^^^^^^^^^^^
  File "C:\Program Files\Python311\Lib\pickle.py", line 1213, in load
    dispatch[key[0]](self)
  File "C:\Users\Manas\AppData\Roaming\Python\Python311\site-packages\joblib\numpy_pickle.py", line 402, in load_build
    Unpickler.load_build(self)
  File "C:\Program Files\Python311\Lib\pickle.py", line 1718, in load_build
    setstate(state)
  File "_tree.pyx", line 848, in sklearn.tree._tree.Tree.__setstate__
  File "_tree.pyx", line 1554, in sklearn.tree._tree._check_node_ndarray
ValueError: node array from the pickle has an incompatible dtype:
- expected: {'names': ['left_child', 'right_child', 'feature', 'threshold', 'impurity', 'n_node_samples', 'weighted_n_node_samples', 'missing_go_to_left'], 'formats': ['<i8', '<i8', '<i8', '<f8', '<f8', '<i8', '<f8', 'u1'], 'offsets': [0, 8, 16, 24, 32, 40, 48, 56], 'itemsize': 64}
- got     : [('left_child', '<i8'), ('right_child', '<i8'), ('feature', '<i8'), ('threshold', '<f8'), ('impurity', '<f8'), ('n_node_samples', '<i8'), ('weighted_n_node_samples', '<f8')]

During handling of the above exception, another exception occurred:

Traceback (most recent call last):
  File "D:\project\Stock_Flipr\backend\python\risk_analysis.py", line 333, in risk_analysis_model
    model, scaler, features_used = load_model_and_scaler(model_path, scaler_path)
                                   ^^^^^^^^^^^^^^^^^^^^^^^^^^^^^^^^^^^^^^^^^^^^^^
  File "D:\project\Stock_Flipr\backend\python\risk_analysis.py", line 306, in load_model_and_scaler
    raise ValueError(f"Failed to load model or scaler: {e}")
ValueError: Failed to load model or scaler: node array from the pickle has an incompatible dtype:
- expected: {'names': ['left_child', 'right_child', 'feature', 'threshold', 'impurity', 'n_node_samples', 'weighted_n_node_samples', 'missing_go_to_left'], 'formats': ['<i8', '<i8', '<i8', '<f8', '<f8', '<i8', '<f8', 'u1'], 'offsets': [0, 8, 16, 24, 32, 40, 48, 56], 'itemsize': 64}
- got     : [('left_child', '<i8'), ('right_child', '<i8'), ('feature', '<i8'), ('threshold', '<f8'), ('impurity', '<f8'), ('n_node_samples', '<i8'), ('weighted_n_node_samples', '<f8')]

2025-05-23 19:38:40,482 - root - INFO - Performing risk analysis for NVDA
2025-05-23 19:38:50,529 - root - INFO - Model for NVDA trained and saved with accuracy: 0.9218
2025-05-23 19:38:56,705 - root - INFO - Performing risk analysis for AMZN
2025-05-23 19:38:57,621 - root - ERROR - Failed to load model or scaler: node array from the pickle has an incompatible dtype:
- expected: {'names': ['left_child', 'right_child', 'feature', 'threshold', 'impurity', 'n_node_samples', 'weighted_n_node_samples', 'missing_go_to_left'], 'formats': ['<i8', '<i8', '<i8', '<f8', '<f8', '<i8', '<f8', 'u1'], 'offsets': [0, 8, 16, 24, 32, 40, 48, 56], 'itemsize': 64}
- got     : [('left_child', '<i8'), ('right_child', '<i8'), ('feature', '<i8'), ('threshold', '<f8'), ('impurity', '<f8'), ('n_node_samples', '<i8'), ('weighted_n_node_samples', '<f8')]
2025-05-23 19:38:57,621 - root - ERROR - Error in risk analysis model for AMZN: Failed to load model or scaler: node array from the pickle has an incompatible dtype:
- expected: {'names': ['left_child', 'right_child', 'feature', 'threshold', 'impurity', 'n_node_samples', 'weighted_n_node_samples', 'missing_go_to_left'], 'formats': ['<i8', '<i8', '<i8', '<f8', '<f8', '<i8', '<f8', 'u1'], 'offsets': [0, 8, 16, 24, 32, 40, 48, 56], 'itemsize': 64}
- got     : [('left_child', '<i8'), ('right_child', '<i8'), ('feature', '<i8'), ('threshold', '<f8'), ('impurity', '<f8'), ('n_node_samples', '<i8'), ('weighted_n_node_samples', '<f8')]
2025-05-23 19:38:57,623 - root - ERROR - Traceback (most recent call last):
  File "D:\project\Stock_Flipr\backend\python\risk_analysis.py", line 292, in load_model_and_scaler
    model = joblib.load(model_path)
            ^^^^^^^^^^^^^^^^^^^^^^^
  File "C:\Users\Manas\AppData\Roaming\Python\Python311\site-packages\joblib\numpy_pickle.py", line 658, in load
    obj = _unpickle(fobj, filename, mmap_mode)
          ^^^^^^^^^^^^^^^^^^^^^^^^^^^^^^^^^^^^
  File "C:\Users\Manas\AppData\Roaming\Python\Python311\site-packages\joblib\numpy_pickle.py", line 577, in _unpickle
    obj = unpickler.load()
          ^^^^^^^^^^^^^^^^
  File "C:\Program Files\Python311\Lib\pickle.py", line 1213, in load
    dispatch[key[0]](self)
  File "C:\Users\Manas\AppData\Roaming\Python\Python311\site-packages\joblib\numpy_pickle.py", line 402, in load_build
    Unpickler.load_build(self)
  File "C:\Program Files\Python311\Lib\pickle.py", line 1718, in load_build
    setstate(state)
  File "_tree.pyx", line 848, in sklearn.tree._tree.Tree.__setstate__
  File "_tree.pyx", line 1554, in sklearn.tree._tree._check_node_ndarray
ValueError: node array from the pickle has an incompatible dtype:
- expected: {'names': ['left_child', 'right_child', 'feature', 'threshold', 'impurity', 'n_node_samples', 'weighted_n_node_samples', 'missing_go_to_left'], 'formats': ['<i8', '<i8', '<i8', '<f8', '<f8', '<i8', '<f8', 'u1'], 'offsets': [0, 8, 16, 24, 32, 40, 48, 56], 'itemsize': 64}
- got     : [('left_child', '<i8'), ('right_child', '<i8'), ('feature', '<i8'), ('threshold', '<f8'), ('impurity', '<f8'), ('n_node_samples', '<i8'), ('weighted_n_node_samples', '<f8')]

During handling of the above exception, another exception occurred:

Traceback (most recent call last):
  File "D:\project\Stock_Flipr\backend\python\risk_analysis.py", line 333, in risk_analysis_model
    model, scaler, features_used = load_model_and_scaler(model_path, scaler_path)
                                   ^^^^^^^^^^^^^^^^^^^^^^^^^^^^^^^^^^^^^^^^^^^^^^
  File "D:\project\Stock_Flipr\backend\python\risk_analysis.py", line 306, in load_model_and_scaler
    raise ValueError(f"Failed to load model or scaler: {e}")
ValueError: Failed to load model or scaler: node array from the pickle has an incompatible dtype:
- expected: {'names': ['left_child', 'right_child', 'feature', 'threshold', 'impurity', 'n_node_samples', 'weighted_n_node_samples', 'missing_go_to_left'], 'formats': ['<i8', '<i8', '<i8', '<f8', '<f8', '<i8', '<f8', 'u1'], 'offsets': [0, 8, 16, 24, 32, 40, 48, 56], 'itemsize': 64}
- got     : [('left_child', '<i8'), ('right_child', '<i8'), ('feature', '<i8'), ('threshold', '<f8'), ('impurity', '<f8'), ('n_node_samples', '<i8'), ('weighted_n_node_samples', '<f8')]

2025-05-23 19:39:09,561 - root - INFO - Performing risk analysis for ZOMATO.BO
2025-05-23 19:40:32,723 - root - INFO - Performing risk analysis for TCS.TO
2025-05-23 19:40:34,036 - root - ERROR - Failed to load model or scaler: node array from the pickle has an incompatible dtype:
- expected: {'names': ['left_child', 'right_child', 'feature', 'threshold', 'impurity', 'n_node_samples', 'weighted_n_node_samples', 'missing_go_to_left'], 'formats': ['<i8', '<i8', '<i8', '<f8', '<f8', '<i8', '<f8', 'u1'], 'offsets': [0, 8, 16, 24, 32, 40, 48, 56], 'itemsize': 64}
- got     : [('left_child', '<i8'), ('right_child', '<i8'), ('feature', '<i8'), ('threshold', '<f8'), ('impurity', '<f8'), ('n_node_samples', '<i8'), ('weighted_n_node_samples', '<f8')]
2025-05-23 19:40:34,038 - root - ERROR - Error in risk analysis model for TCS.TO: Failed to load model or scaler: node array from the pickle has an incompatible dtype:
- expected: {'names': ['left_child', 'right_child', 'feature', 'threshold', 'impurity', 'n_node_samples', 'weighted_n_node_samples', 'missing_go_to_left'], 'formats': ['<i8', '<i8', '<i8', '<f8', '<f8', '<i8', '<f8', 'u1'], 'offsets': [0, 8, 16, 24, 32, 40, 48, 56], 'itemsize': 64}
- got     : [('left_child', '<i8'), ('right_child', '<i8'), ('feature', '<i8'), ('threshold', '<f8'), ('impurity', '<f8'), ('n_node_samples', '<i8'), ('weighted_n_node_samples', '<f8')]
2025-05-23 19:40:34,039 - root - ERROR - Traceback (most recent call last):
  File "D:\project\Stock_Flipr\backend\python\risk_analysis.py", line 292, in load_model_and_scaler
    model = joblib.load(model_path)
            ^^^^^^^^^^^^^^^^^^^^^^^
  File "C:\Users\Manas\AppData\Roaming\Python\Python311\site-packages\joblib\numpy_pickle.py", line 658, in load
    obj = _unpickle(fobj, filename, mmap_mode)
          ^^^^^^^^^^^^^^^^^^^^^^^^^^^^^^^^^^^^
  File "C:\Users\Manas\AppData\Roaming\Python\Python311\site-packages\joblib\numpy_pickle.py", line 577, in _unpickle
    obj = unpickler.load()
          ^^^^^^^^^^^^^^^^
  File "C:\Program Files\Python311\Lib\pickle.py", line 1213, in load
    dispatch[key[0]](self)
  File "C:\Users\Manas\AppData\Roaming\Python\Python311\site-packages\joblib\numpy_pickle.py", line 402, in load_build
    Unpickler.load_build(self)
  File "C:\Program Files\Python311\Lib\pickle.py", line 1718, in load_build
    setstate(state)
  File "_tree.pyx", line 848, in sklearn.tree._tree.Tree.__setstate__
  File "_tree.pyx", line 1554, in sklearn.tree._tree._check_node_ndarray
ValueError: node array from the pickle has an incompatible dtype:
- expected: {'names': ['left_child', 'right_child', 'feature', 'threshold', 'impurity', 'n_node_samples', 'weighted_n_node_samples', 'missing_go_to_left'], 'formats': ['<i8', '<i8', '<i8', '<f8', '<f8', '<i8', '<f8', 'u1'], 'offsets': [0, 8, 16, 24, 32, 40, 48, 56], 'itemsize': 64}
- got     : [('left_child', '<i8'), ('right_child', '<i8'), ('feature', '<i8'), ('threshold', '<f8'), ('impurity', '<f8'), ('n_node_samples', '<i8'), ('weighted_n_node_samples', '<f8')]

During handling of the above exception, another exception occurred:

Traceback (most recent call last):
  File "D:\project\Stock_Flipr\backend\python\risk_analysis.py", line 333, in risk_analysis_model
    model, scaler, features_used = load_model_and_scaler(model_path, scaler_path)
                                   ^^^^^^^^^^^^^^^^^^^^^^^^^^^^^^^^^^^^^^^^^^^^^^
  File "D:\project\Stock_Flipr\backend\python\risk_analysis.py", line 306, in load_model_and_scaler
    raise ValueError(f"Failed to load model or scaler: {e}")
ValueError: Failed to load model or scaler: node array from the pickle has an incompatible dtype:
- expected: {'names': ['left_child', 'right_child', 'feature', 'threshold', 'impurity', 'n_node_samples', 'weighted_n_node_samples', 'missing_go_to_left'], 'formats': ['<i8', '<i8', '<i8', '<f8', '<f8', '<i8', '<f8', 'u1'], 'offsets': [0, 8, 16, 24, 32, 40, 48, 56], 'itemsize': 64}
- got     : [('left_child', '<i8'), ('right_child', '<i8'), ('feature', '<i8'), ('threshold', '<f8'), ('impurity', '<f8'), ('n_node_samples', '<i8'), ('weighted_n_node_samples', '<f8')]

2025-05-23 19:41:03,107 - root - INFO - Performing risk analysis for CIPLA.NS
2025-05-23 19:41:04,412 - root - ERROR - Error training model for CIPLA.NS: Input X contains infinity or a value too large for dtype('float64').
2025-05-23 19:41:04,471 - root - ERROR - Traceback (most recent call last):
  File "D:\project\Stock_Flipr\backend\python\risk_analysis.py", line 234, in train_and_save_model
    X_test_scaled = scaler.transform(X_test)
                    ^^^^^^^^^^^^^^^^^^^^^^^^
  File "C:\Users\Manas\AppData\Roaming\Python\Python311\site-packages\sklearn\utils\_set_output.py", line 319, in wrapped
    data_to_wrap = f(self, X, *args, **kwargs)
                   ^^^^^^^^^^^^^^^^^^^^^^^^^^^
  File "C:\Users\Manas\AppData\Roaming\Python\Python311\site-packages\sklearn\preprocessing\_data.py", line 1062, in transform
    X = validate_data(
        ^^^^^^^^^^^^^^
  File "C:\Users\Manas\AppData\Roaming\Python\Python311\site-packages\sklearn\utils\validation.py", line 2944, in validate_data
    out = check_array(X, input_name="X", **check_params)
          ^^^^^^^^^^^^^^^^^^^^^^^^^^^^^^^^^^^^^^^^^^^^^^
  File "C:\Users\Manas\AppData\Roaming\Python\Python311\site-packages\sklearn\utils\validation.py", line 1107, in check_array
    _assert_all_finite(
  File "C:\Users\Manas\AppData\Roaming\Python\Python311\site-packages\sklearn\utils\validation.py", line 120, in _assert_all_finite
    _assert_all_finite_element_wise(
  File "C:\Users\Manas\AppData\Roaming\Python\Python311\site-packages\sklearn\utils\validation.py", line 169, in _assert_all_finite_element_wise
    raise ValueError(msg_err)
ValueError: Input X contains infinity or a value too large for dtype('float64').

2025-05-23 19:41:04,471 - root - ERROR - Error in risk analysis model for CIPLA.NS: Error training and saving model for CIPLA.NS: Input X contains infinity or a value too large for dtype('float64').
2025-05-23 19:41:04,472 - root - ERROR - Traceback (most recent call last):
  File "D:\project\Stock_Flipr\backend\python\risk_analysis.py", line 234, in train_and_save_model
    X_test_scaled = scaler.transform(X_test)
                    ^^^^^^^^^^^^^^^^^^^^^^^^
  File "C:\Users\Manas\AppData\Roaming\Python\Python311\site-packages\sklearn\utils\_set_output.py", line 319, in wrapped
    data_to_wrap = f(self, X, *args, **kwargs)
                   ^^^^^^^^^^^^^^^^^^^^^^^^^^^
  File "C:\Users\Manas\AppData\Roaming\Python\Python311\site-packages\sklearn\preprocessing\_data.py", line 1062, in transform
    X = validate_data(
        ^^^^^^^^^^^^^^
  File "C:\Users\Manas\AppData\Roaming\Python\Python311\site-packages\sklearn\utils\validation.py", line 2944, in validate_data
    out = check_array(X, input_name="X", **check_params)
          ^^^^^^^^^^^^^^^^^^^^^^^^^^^^^^^^^^^^^^^^^^^^^^
  File "C:\Users\Manas\AppData\Roaming\Python\Python311\site-packages\sklearn\utils\validation.py", line 1107, in check_array
    _assert_all_finite(
  File "C:\Users\Manas\AppData\Roaming\Python\Python311\site-packages\sklearn\utils\validation.py", line 120, in _assert_all_finite
    _assert_all_finite_element_wise(
  File "C:\Users\Manas\AppData\Roaming\Python\Python311\site-packages\sklearn\utils\validation.py", line 169, in _assert_all_finite_element_wise
    raise ValueError(msg_err)
ValueError: Input X contains infinity or a value too large for dtype('float64').

During handling of the above exception, another exception occurred:

Traceback (most recent call last):
  File "D:\project\Stock_Flipr\backend\python\risk_analysis.py", line 331, in risk_analysis_model
    model, scaler, features_used = train_and_save_model(new_stock_ticker, model_path, scaler_path)
                                   ^^^^^^^^^^^^^^^^^^^^^^^^^^^^^^^^^^^^^^^^^^^^^^^^^^^^^^^^^^^^^^^
  File "D:\project\Stock_Flipr\backend\python\risk_analysis.py", line 285, in train_and_save_model
    raise ValueError(f"Error training and saving model for {ticker}: {e}")
ValueError: Error training and saving model for CIPLA.NS: Input X contains infinity or a value too large for dtype('float64').

2025-05-23 19:41:12,448 - root - INFO - Performing risk analysis for CIPLA.BO
2025-05-23 19:41:22,243 - root - INFO - Model for CIPLA.BO trained and saved with accuracy: 0.9156
2025-05-23 19:42:46,876 - root - INFO - Performing risk analysis for AAPL
2025-05-23 19:43:24,580 - root - INFO - Performing risk analysis for TSLA
2025-05-23 19:43:34,818 - root - INFO - Model for TSLA trained and saved with accuracy: 0.9636
2025-05-23 19:43:51,638 - root - INFO - Performing risk analysis for ZOMATO.BO
2025-05-23 19:44:27,012 - root - INFO - Performing risk analysis for TCS.BO
2025-05-23 19:44:39,121 - root - INFO - Model for TCS.BO trained and saved with accuracy: 0.8467
2025-05-23 19:44:50,169 - root - INFO - Performing risk analysis for TCS.NS
2025-05-23 19:44:51,252 - root - ERROR - Error training model for TCS.NS: Input X contains infinity or a value too large for dtype('float64').
2025-05-23 19:44:51,256 - root - ERROR - Traceback (most recent call last):
  File "D:\project\Stock_Flipr\backend\python\risk_analysis.py", line 234, in train_and_save_model
    X_test_scaled = scaler.transform(X_test)
                    ^^^^^^^^^^^^^^^^^^^^^^^^
  File "C:\Users\Manas\AppData\Roaming\Python\Python311\site-packages\sklearn\utils\_set_output.py", line 319, in wrapped
    data_to_wrap = f(self, X, *args, **kwargs)
                   ^^^^^^^^^^^^^^^^^^^^^^^^^^^
  File "C:\Users\Manas\AppData\Roaming\Python\Python311\site-packages\sklearn\preprocessing\_data.py", line 1062, in transform
    X = validate_data(
        ^^^^^^^^^^^^^^
  File "C:\Users\Manas\AppData\Roaming\Python\Python311\site-packages\sklearn\utils\validation.py", line 2944, in validate_data
    out = check_array(X, input_name="X", **check_params)
          ^^^^^^^^^^^^^^^^^^^^^^^^^^^^^^^^^^^^^^^^^^^^^^
  File "C:\Users\Manas\AppData\Roaming\Python\Python311\site-packages\sklearn\utils\validation.py", line 1107, in check_array
    _assert_all_finite(
  File "C:\Users\Manas\AppData\Roaming\Python\Python311\site-packages\sklearn\utils\validation.py", line 120, in _assert_all_finite
    _assert_all_finite_element_wise(
  File "C:\Users\Manas\AppData\Roaming\Python\Python311\site-packages\sklearn\utils\validation.py", line 169, in _assert_all_finite_element_wise
    raise ValueError(msg_err)
ValueError: Input X contains infinity or a value too large for dtype('float64').

2025-05-23 19:44:51,256 - root - ERROR - Error in risk analysis model for TCS.NS: Error training and saving model for TCS.NS: Input X contains infinity or a value too large for dtype('float64').
2025-05-23 19:44:51,257 - root - ERROR - Traceback (most recent call last):
  File "D:\project\Stock_Flipr\backend\python\risk_analysis.py", line 234, in train_and_save_model
    X_test_scaled = scaler.transform(X_test)
                    ^^^^^^^^^^^^^^^^^^^^^^^^
  File "C:\Users\Manas\AppData\Roaming\Python\Python311\site-packages\sklearn\utils\_set_output.py", line 319, in wrapped
    data_to_wrap = f(self, X, *args, **kwargs)
                   ^^^^^^^^^^^^^^^^^^^^^^^^^^^
  File "C:\Users\Manas\AppData\Roaming\Python\Python311\site-packages\sklearn\preprocessing\_data.py", line 1062, in transform
    X = validate_data(
        ^^^^^^^^^^^^^^
  File "C:\Users\Manas\AppData\Roaming\Python\Python311\site-packages\sklearn\utils\validation.py", line 2944, in validate_data
    out = check_array(X, input_name="X", **check_params)
          ^^^^^^^^^^^^^^^^^^^^^^^^^^^^^^^^^^^^^^^^^^^^^^
  File "C:\Users\Manas\AppData\Roaming\Python\Python311\site-packages\sklearn\utils\validation.py", line 1107, in check_array
    _assert_all_finite(
  File "C:\Users\Manas\AppData\Roaming\Python\Python311\site-packages\sklearn\utils\validation.py", line 120, in _assert_all_finite
    _assert_all_finite_element_wise(
  File "C:\Users\Manas\AppData\Roaming\Python\Python311\site-packages\sklearn\utils\validation.py", line 169, in _assert_all_finite_element_wise
    raise ValueError(msg_err)
ValueError: Input X contains infinity or a value too large for dtype('float64').

During handling of the above exception, another exception occurred:

Traceback (most recent call last):
  File "D:\project\Stock_Flipr\backend\python\risk_analysis.py", line 331, in risk_analysis_model
    model, scaler, features_used = train_and_save_model(new_stock_ticker, model_path, scaler_path)
                                   ^^^^^^^^^^^^^^^^^^^^^^^^^^^^^^^^^^^^^^^^^^^^^^^^^^^^^^^^^^^^^^^
  File "D:\project\Stock_Flipr\backend\python\risk_analysis.py", line 285, in train_and_save_model
    raise ValueError(f"Error training and saving model for {ticker}: {e}")
ValueError: Error training and saving model for TCS.NS: Input X contains infinity or a value too large for dtype('float64').

2025-05-23 19:45:11,655 - root - INFO - Performing risk analysis for HAL
2025-05-23 19:45:22,373 - root - INFO - Model for HAL trained and saved with accuracy: 0.9218
2025-05-23 19:48:10,082 - root - INFO - Performing risk analysis for AMZN
2025-05-23 19:48:10,926 - root - ERROR - Failed to load model or scaler: node array from the pickle has an incompatible dtype:
- expected: {'names': ['left_child', 'right_child', 'feature', 'threshold', 'impurity', 'n_node_samples', 'weighted_n_node_samples', 'missing_go_to_left'], 'formats': ['<i8', '<i8', '<i8', '<f8', '<f8', '<i8', '<f8', 'u1'], 'offsets': [0, 8, 16, 24, 32, 40, 48, 56], 'itemsize': 64}
- got     : [('left_child', '<i8'), ('right_child', '<i8'), ('feature', '<i8'), ('threshold', '<f8'), ('impurity', '<f8'), ('n_node_samples', '<i8'), ('weighted_n_node_samples', '<f8')]
2025-05-23 19:48:10,926 - root - ERROR - Error in risk analysis model for AMZN: Failed to load model or scaler: node array from the pickle has an incompatible dtype:
- expected: {'names': ['left_child', 'right_child', 'feature', 'threshold', 'impurity', 'n_node_samples', 'weighted_n_node_samples', 'missing_go_to_left'], 'formats': ['<i8', '<i8', '<i8', '<f8', '<f8', '<i8', '<f8', 'u1'], 'offsets': [0, 8, 16, 24, 32, 40, 48, 56], 'itemsize': 64}
- got     : [('left_child', '<i8'), ('right_child', '<i8'), ('feature', '<i8'), ('threshold', '<f8'), ('impurity', '<f8'), ('n_node_samples', '<i8'), ('weighted_n_node_samples', '<f8')]
2025-05-23 19:48:10,928 - root - ERROR - Traceback (most recent call last):
  File "D:\project\Stock_Flipr\backend\python\risk_analysis.py", line 292, in load_model_and_scaler
    model = joblib.load(model_path)
            ^^^^^^^^^^^^^^^^^^^^^^^
  File "C:\Users\Manas\AppData\Roaming\Python\Python311\site-packages\joblib\numpy_pickle.py", line 658, in load
    obj = _unpickle(fobj, filename, mmap_mode)
          ^^^^^^^^^^^^^^^^^^^^^^^^^^^^^^^^^^^^
  File "C:\Users\Manas\AppData\Roaming\Python\Python311\site-packages\joblib\numpy_pickle.py", line 577, in _unpickle
    obj = unpickler.load()
          ^^^^^^^^^^^^^^^^
  File "C:\Program Files\Python311\Lib\pickle.py", line 1213, in load
    dispatch[key[0]](self)
  File "C:\Users\Manas\AppData\Roaming\Python\Python311\site-packages\joblib\numpy_pickle.py", line 402, in load_build
    Unpickler.load_build(self)
  File "C:\Program Files\Python311\Lib\pickle.py", line 1718, in load_build
    setstate(state)
  File "_tree.pyx", line 848, in sklearn.tree._tree.Tree.__setstate__
  File "_tree.pyx", line 1554, in sklearn.tree._tree._check_node_ndarray
ValueError: node array from the pickle has an incompatible dtype:
- expected: {'names': ['left_child', 'right_child', 'feature', 'threshold', 'impurity', 'n_node_samples', 'weighted_n_node_samples', 'missing_go_to_left'], 'formats': ['<i8', '<i8', '<i8', '<f8', '<f8', '<i8', '<f8', 'u1'], 'offsets': [0, 8, 16, 24, 32, 40, 48, 56], 'itemsize': 64}
- got     : [('left_child', '<i8'), ('right_child', '<i8'), ('feature', '<i8'), ('threshold', '<f8'), ('impurity', '<f8'), ('n_node_samples', '<i8'), ('weighted_n_node_samples', '<f8')]

During handling of the above exception, another exception occurred:

Traceback (most recent call last):
  File "D:\project\Stock_Flipr\backend\python\risk_analysis.py", line 333, in risk_analysis_model
    model, scaler, features_used = load_model_and_scaler(model_path, scaler_path)
                                   ^^^^^^^^^^^^^^^^^^^^^^^^^^^^^^^^^^^^^^^^^^^^^^
  File "D:\project\Stock_Flipr\backend\python\risk_analysis.py", line 306, in load_model_and_scaler
    raise ValueError(f"Failed to load model or scaler: {e}")
ValueError: Failed to load model or scaler: node array from the pickle has an incompatible dtype:
- expected: {'names': ['left_child', 'right_child', 'feature', 'threshold', 'impurity', 'n_node_samples', 'weighted_n_node_samples', 'missing_go_to_left'], 'formats': ['<i8', '<i8', '<i8', '<f8', '<f8', '<i8', '<f8', 'u1'], 'offsets': [0, 8, 16, 24, 32, 40, 48, 56], 'itemsize': 64}
- got     : [('left_child', '<i8'), ('right_child', '<i8'), ('feature', '<i8'), ('threshold', '<f8'), ('impurity', '<f8'), ('n_node_samples', '<i8'), ('weighted_n_node_samples', '<f8')]

2025-05-23 21:06:50,883 - root - INFO - Performing risk analysis for GOOGL
2025-05-23 21:06:53,350 - root - ERROR - Error in risk analysis model for GOOGL: module 'yfinance.shared' has no attribute 'exceptions'
2025-05-23 21:06:53,362 - root - ERROR - Traceback (most recent call last):
  File "E:\Stock\backend\python\risk_analysis.py", line 58, in get_stock_data
    hist = stock.history(period=period, interval=interval)
           ^^^^^^^^^^^^^^^^^^^^^^^^^^^^^^^^^^^^^^^^^^^^^^^
  File "C:\Users\Manas\AppData\Roaming\Python\Python311\site-packages\yfinance\utils.py", line 104, in wrapper
    result = func(*args, **kwargs)
             ^^^^^^^^^^^^^^^^^^^^^
  File "C:\Users\Manas\AppData\Roaming\Python\Python311\site-packages\yfinance\base.py", line 82, in history
    return self._lazy_load_price_history().history(*args, **kwargs)
           ^^^^^^^^^^^^^^^^^^^^^^^^^^^^^^^^^^^^^^^^^^^^^^^^^^^^^^^^
  File "C:\Users\Manas\AppData\Roaming\Python\Python311\site-packages\yfinance\utils.py", line 104, in wrapper
    result = func(*args, **kwargs)
             ^^^^^^^^^^^^^^^^^^^^^
  File "C:\Users\Manas\AppData\Roaming\Python\Python311\site-packages\yfinance\scrapers\history.py", line 175, in history
    data = get_fn(
           ^^^^^^^
  File "C:\Users\Manas\AppData\Roaming\Python\Python311\site-packages\yfinance\utils.py", line 104, in wrapper
    result = func(*args, **kwargs)
             ^^^^^^^^^^^^^^^^^^^^^
  File "C:\Users\Manas\AppData\Roaming\Python\Python311\site-packages\yfinance\data.py", line 349, in get
    return self._make_request(url, request_method = self._session.get, user_agent_headers=user_agent_headers, params=params, proxy=proxy, timeout=timeout)
           ^^^^^^^^^^^^^^^^^^^^^^^^^^^^^^^^^^^^^^^^^^^^^^^^^^^^^^^^^^^^^^^^^^^^^^^^^^^^^^^^^^^^^^^^^^^^^^^^^^^^^^^^^^^^^^^^^^^^^^^^^^^^^^^^^^^^^^^^^^^^^^^
  File "C:\Users\Manas\AppData\Roaming\Python\Python311\site-packages\yfinance\utils.py", line 104, in wrapper
    result = func(*args, **kwargs)
             ^^^^^^^^^^^^^^^^^^^^^
  File "C:\Users\Manas\AppData\Roaming\Python\Python311\site-packages\yfinance\data.py", line 411, in _make_request
    raise YFRateLimitError()
yfinance.exceptions.YFRateLimitError: Too Many Requests. Rate limited. Try after a while.

During handling of the above exception, another exception occurred:

Traceback (most recent call last):
  File "E:\Stock\backend\python\risk_analysis.py", line 314, in risk_analysis_model
    data = get_stock_data(new_stock_ticker)
           ^^^^^^^^^^^^^^^^^^^^^^^^^^^^^^^^
  File "E:\Stock\backend\python\risk_analysis.py", line 73, in get_stock_data
    except yf.shared.exceptions.YFinanceError as yfe:
           ^^^^^^^^^^^^^^^^^^^^
AttributeError: module 'yfinance.shared' has no attribute 'exceptions'

2025-05-23 21:06:59,309 - root - INFO - Performing risk analysis for GOOGL
2025-05-23 21:07:01,776 - root - ERROR - Error in risk analysis model for GOOGL: module 'yfinance.shared' has no attribute 'exceptions'
2025-05-23 21:07:01,791 - root - ERROR - Traceback (most recent call last):
  File "E:\Stock\backend\python\risk_analysis.py", line 58, in get_stock_data
    hist = stock.history(period=period, interval=interval)
           ^^^^^^^^^^^^^^^^^^^^^^^^^^^^^^^^^^^^^^^^^^^^^^^
  File "C:\Users\Manas\AppData\Roaming\Python\Python311\site-packages\yfinance\utils.py", line 104, in wrapper
    result = func(*args, **kwargs)
             ^^^^^^^^^^^^^^^^^^^^^
  File "C:\Users\Manas\AppData\Roaming\Python\Python311\site-packages\yfinance\base.py", line 82, in history
    return self._lazy_load_price_history().history(*args, **kwargs)
           ^^^^^^^^^^^^^^^^^^^^^^^^^^^^^^^^^^^^^^^^^^^^^^^^^^^^^^^^
  File "C:\Users\Manas\AppData\Roaming\Python\Python311\site-packages\yfinance\utils.py", line 104, in wrapper
    result = func(*args, **kwargs)
             ^^^^^^^^^^^^^^^^^^^^^
  File "C:\Users\Manas\AppData\Roaming\Python\Python311\site-packages\yfinance\scrapers\history.py", line 175, in history
    data = get_fn(
           ^^^^^^^
  File "C:\Users\Manas\AppData\Roaming\Python\Python311\site-packages\yfinance\utils.py", line 104, in wrapper
    result = func(*args, **kwargs)
             ^^^^^^^^^^^^^^^^^^^^^
  File "C:\Users\Manas\AppData\Roaming\Python\Python311\site-packages\yfinance\data.py", line 349, in get
    return self._make_request(url, request_method = self._session.get, user_agent_headers=user_agent_headers, params=params, proxy=proxy, timeout=timeout)
           ^^^^^^^^^^^^^^^^^^^^^^^^^^^^^^^^^^^^^^^^^^^^^^^^^^^^^^^^^^^^^^^^^^^^^^^^^^^^^^^^^^^^^^^^^^^^^^^^^^^^^^^^^^^^^^^^^^^^^^^^^^^^^^^^^^^^^^^^^^^^^^^
  File "C:\Users\Manas\AppData\Roaming\Python\Python311\site-packages\yfinance\utils.py", line 104, in wrapper
    result = func(*args, **kwargs)
             ^^^^^^^^^^^^^^^^^^^^^
  File "C:\Users\Manas\AppData\Roaming\Python\Python311\site-packages\yfinance\data.py", line 411, in _make_request
    raise YFRateLimitError()
yfinance.exceptions.YFRateLimitError: Too Many Requests. Rate limited. Try after a while.

During handling of the above exception, another exception occurred:

Traceback (most recent call last):
  File "E:\Stock\backend\python\risk_analysis.py", line 314, in risk_analysis_model
    data = get_stock_data(new_stock_ticker)
           ^^^^^^^^^^^^^^^^^^^^^^^^^^^^^^^^
  File "E:\Stock\backend\python\risk_analysis.py", line 73, in get_stock_data
    except yf.shared.exceptions.YFinanceError as yfe:
           ^^^^^^^^^^^^^^^^^^^^
AttributeError: module 'yfinance.shared' has no attribute 'exceptions'

2025-05-23 21:10:07,780 - root - INFO - Performing risk analysis for AAPL
2025-05-23 21:10:09,910 - root - ERROR - Error in risk analysis model for AAPL: module 'yfinance.shared' has no attribute 'exceptions'
2025-05-23 21:10:09,925 - root - ERROR - Traceback (most recent call last):
  File "E:\Stock\backend\python\risk_analysis.py", line 58, in get_stock_data
    hist = stock.history(period=period, interval=interval)
           ^^^^^^^^^^^^^^^^^^^^^^^^^^^^^^^^^^^^^^^^^^^^^^^
  File "C:\Users\Manas\AppData\Roaming\Python\Python311\site-packages\yfinance\utils.py", line 104, in wrapper
    result = func(*args, **kwargs)
             ^^^^^^^^^^^^^^^^^^^^^
  File "C:\Users\Manas\AppData\Roaming\Python\Python311\site-packages\yfinance\base.py", line 82, in history
    return self._lazy_load_price_history().history(*args, **kwargs)
           ^^^^^^^^^^^^^^^^^^^^^^^^^^^^^^^^^^^^^^^^^^^^^^^^^^^^^^^^
  File "C:\Users\Manas\AppData\Roaming\Python\Python311\site-packages\yfinance\utils.py", line 104, in wrapper
    result = func(*args, **kwargs)
             ^^^^^^^^^^^^^^^^^^^^^
  File "C:\Users\Manas\AppData\Roaming\Python\Python311\site-packages\yfinance\scrapers\history.py", line 175, in history
    data = get_fn(
           ^^^^^^^
  File "C:\Users\Manas\AppData\Roaming\Python\Python311\site-packages\yfinance\utils.py", line 104, in wrapper
    result = func(*args, **kwargs)
             ^^^^^^^^^^^^^^^^^^^^^
  File "C:\Users\Manas\AppData\Roaming\Python\Python311\site-packages\yfinance\data.py", line 349, in get
    return self._make_request(url, request_method = self._session.get, user_agent_headers=user_agent_headers, params=params, proxy=proxy, timeout=timeout)
           ^^^^^^^^^^^^^^^^^^^^^^^^^^^^^^^^^^^^^^^^^^^^^^^^^^^^^^^^^^^^^^^^^^^^^^^^^^^^^^^^^^^^^^^^^^^^^^^^^^^^^^^^^^^^^^^^^^^^^^^^^^^^^^^^^^^^^^^^^^^^^^^
  File "C:\Users\Manas\AppData\Roaming\Python\Python311\site-packages\yfinance\utils.py", line 104, in wrapper
    result = func(*args, **kwargs)
             ^^^^^^^^^^^^^^^^^^^^^
  File "C:\Users\Manas\AppData\Roaming\Python\Python311\site-packages\yfinance\data.py", line 411, in _make_request
    raise YFRateLimitError()
yfinance.exceptions.YFRateLimitError: Too Many Requests. Rate limited. Try after a while.

During handling of the above exception, another exception occurred:

Traceback (most recent call last):
  File "E:\Stock\backend\python\risk_analysis.py", line 314, in risk_analysis_model
    data = get_stock_data(new_stock_ticker)
           ^^^^^^^^^^^^^^^^^^^^^^^^^^^^^^^^
  File "E:\Stock\backend\python\risk_analysis.py", line 73, in get_stock_data
    except yf.shared.exceptions.YFinanceError as yfe:
           ^^^^^^^^^^^^^^^^^^^^
AttributeError: module 'yfinance.shared' has no attribute 'exceptions'

2025-05-23 22:49:44,514 - root - INFO - Performing risk analysis for GOOGL
2025-05-23 22:49:47,056 - root - ERROR - Error in risk analysis model for GOOGL: module 'yfinance.shared' has no attribute 'exceptions'
2025-05-23 22:49:47,060 - root - ERROR - Traceback (most recent call last):
  File "E:\Stock\backend\python\risk_analysis.py", line 58, in get_stock_data
    hist = stock.history(period=period, interval=interval)
           ^^^^^^^^^^^^^^^^^^^^^^^^^^^^^^^^^^^^^^^^^^^^^^^
  File "C:\Users\Manas\AppData\Roaming\Python\Python311\site-packages\yfinance\utils.py", line 104, in wrapper
    result = func(*args, **kwargs)
             ^^^^^^^^^^^^^^^^^^^^^
  File "C:\Users\Manas\AppData\Roaming\Python\Python311\site-packages\yfinance\base.py", line 82, in history
    return self._lazy_load_price_history().history(*args, **kwargs)
           ^^^^^^^^^^^^^^^^^^^^^^^^^^^^^^^^^^^^^^^^^^^^^^^^^^^^^^^^
  File "C:\Users\Manas\AppData\Roaming\Python\Python311\site-packages\yfinance\utils.py", line 104, in wrapper
    result = func(*args, **kwargs)
             ^^^^^^^^^^^^^^^^^^^^^
  File "C:\Users\Manas\AppData\Roaming\Python\Python311\site-packages\yfinance\scrapers\history.py", line 175, in history
    data = get_fn(
           ^^^^^^^
  File "C:\Users\Manas\AppData\Roaming\Python\Python311\site-packages\yfinance\utils.py", line 104, in wrapper
    result = func(*args, **kwargs)
             ^^^^^^^^^^^^^^^^^^^^^
  File "C:\Users\Manas\AppData\Roaming\Python\Python311\site-packages\yfinance\data.py", line 349, in get
    return self._make_request(url, request_method = self._session.get, user_agent_headers=user_agent_headers, params=params, proxy=proxy, timeout=timeout)
           ^^^^^^^^^^^^^^^^^^^^^^^^^^^^^^^^^^^^^^^^^^^^^^^^^^^^^^^^^^^^^^^^^^^^^^^^^^^^^^^^^^^^^^^^^^^^^^^^^^^^^^^^^^^^^^^^^^^^^^^^^^^^^^^^^^^^^^^^^^^^^^^
  File "C:\Users\Manas\AppData\Roaming\Python\Python311\site-packages\yfinance\utils.py", line 104, in wrapper
    result = func(*args, **kwargs)
             ^^^^^^^^^^^^^^^^^^^^^
  File "C:\Users\Manas\AppData\Roaming\Python\Python311\site-packages\yfinance\data.py", line 411, in _make_request
    raise YFRateLimitError()
yfinance.exceptions.YFRateLimitError: Too Many Requests. Rate limited. Try after a while.

During handling of the above exception, another exception occurred:

Traceback (most recent call last):
  File "E:\Stock\backend\python\risk_analysis.py", line 314, in risk_analysis_model
    data = get_stock_data(new_stock_ticker)
           ^^^^^^^^^^^^^^^^^^^^^^^^^^^^^^^^
  File "E:\Stock\backend\python\risk_analysis.py", line 73, in get_stock_data
    except yf.shared.exceptions.YFinanceError as yfe:
           ^^^^^^^^^^^^^^^^^^^^
AttributeError: module 'yfinance.shared' has no attribute 'exceptions'

2025-05-23 22:49:49,124 - root - INFO - Performing risk analysis for GOOGL
2025-05-23 22:49:51,337 - root - ERROR - Error in risk analysis model for GOOGL: module 'yfinance.shared' has no attribute 'exceptions'
2025-05-23 22:49:51,340 - root - ERROR - Traceback (most recent call last):
  File "E:\Stock\backend\python\risk_analysis.py", line 58, in get_stock_data
    hist = stock.history(period=period, interval=interval)
           ^^^^^^^^^^^^^^^^^^^^^^^^^^^^^^^^^^^^^^^^^^^^^^^
  File "C:\Users\Manas\AppData\Roaming\Python\Python311\site-packages\yfinance\utils.py", line 104, in wrapper
    result = func(*args, **kwargs)
             ^^^^^^^^^^^^^^^^^^^^^
  File "C:\Users\Manas\AppData\Roaming\Python\Python311\site-packages\yfinance\base.py", line 82, in history
    return self._lazy_load_price_history().history(*args, **kwargs)
           ^^^^^^^^^^^^^^^^^^^^^^^^^^^^^^^^^^^^^^^^^^^^^^^^^^^^^^^^
  File "C:\Users\Manas\AppData\Roaming\Python\Python311\site-packages\yfinance\utils.py", line 104, in wrapper
    result = func(*args, **kwargs)
             ^^^^^^^^^^^^^^^^^^^^^
  File "C:\Users\Manas\AppData\Roaming\Python\Python311\site-packages\yfinance\scrapers\history.py", line 175, in history
    data = get_fn(
           ^^^^^^^
  File "C:\Users\Manas\AppData\Roaming\Python\Python311\site-packages\yfinance\utils.py", line 104, in wrapper
    result = func(*args, **kwargs)
             ^^^^^^^^^^^^^^^^^^^^^
  File "C:\Users\Manas\AppData\Roaming\Python\Python311\site-packages\yfinance\data.py", line 349, in get
    return self._make_request(url, request_method = self._session.get, user_agent_headers=user_agent_headers, params=params, proxy=proxy, timeout=timeout)
           ^^^^^^^^^^^^^^^^^^^^^^^^^^^^^^^^^^^^^^^^^^^^^^^^^^^^^^^^^^^^^^^^^^^^^^^^^^^^^^^^^^^^^^^^^^^^^^^^^^^^^^^^^^^^^^^^^^^^^^^^^^^^^^^^^^^^^^^^^^^^^^^
  File "C:\Users\Manas\AppData\Roaming\Python\Python311\site-packages\yfinance\utils.py", line 104, in wrapper
    result = func(*args, **kwargs)
             ^^^^^^^^^^^^^^^^^^^^^
  File "C:\Users\Manas\AppData\Roaming\Python\Python311\site-packages\yfinance\data.py", line 411, in _make_request
    raise YFRateLimitError()
yfinance.exceptions.YFRateLimitError: Too Many Requests. Rate limited. Try after a while.

During handling of the above exception, another exception occurred:

Traceback (most recent call last):
  File "E:\Stock\backend\python\risk_analysis.py", line 314, in risk_analysis_model
    data = get_stock_data(new_stock_ticker)
           ^^^^^^^^^^^^^^^^^^^^^^^^^^^^^^^^
  File "E:\Stock\backend\python\risk_analysis.py", line 73, in get_stock_data
    except yf.shared.exceptions.YFinanceError as yfe:
           ^^^^^^^^^^^^^^^^^^^^
AttributeError: module 'yfinance.shared' has no attribute 'exceptions'

2025-05-25 14:28:02,370 - root - INFO - Performing risk analysis for AAPL
2025-05-25 14:28:06,297 - root - ERROR - Error in risk analysis model for AAPL: module 'yfinance.shared' has no attribute 'exceptions'
2025-05-25 14:28:06,339 - root - ERROR - Traceback (most recent call last):
  File "E:\Stock\backend\python\risk_analysis.py", line 58, in get_stock_data
    hist = stock.history(period=period, interval=interval)
           ^^^^^^^^^^^^^^^^^^^^^^^^^^^^^^^^^^^^^^^^^^^^^^^
  File "C:\Users\Manas\AppData\Roaming\Python\Python311\site-packages\yfinance\utils.py", line 104, in wrapper
    result = func(*args, **kwargs)
             ^^^^^^^^^^^^^^^^^^^^^
  File "C:\Users\Manas\AppData\Roaming\Python\Python311\site-packages\yfinance\base.py", line 82, in history
    return self._lazy_load_price_history().history(*args, **kwargs)
           ^^^^^^^^^^^^^^^^^^^^^^^^^^^^^^^^^^^^^^^^^^^^^^^^^^^^^^^^
  File "C:\Users\Manas\AppData\Roaming\Python\Python311\site-packages\yfinance\utils.py", line 104, in wrapper
    result = func(*args, **kwargs)
             ^^^^^^^^^^^^^^^^^^^^^
  File "C:\Users\Manas\AppData\Roaming\Python\Python311\site-packages\yfinance\scrapers\history.py", line 175, in history
    data = get_fn(
           ^^^^^^^
  File "C:\Users\Manas\AppData\Roaming\Python\Python311\site-packages\yfinance\utils.py", line 104, in wrapper
    result = func(*args, **kwargs)
             ^^^^^^^^^^^^^^^^^^^^^
  File "C:\Users\Manas\AppData\Roaming\Python\Python311\site-packages\yfinance\data.py", line 349, in get
    return self._make_request(url, request_method = self._session.get, user_agent_headers=user_agent_headers, params=params, proxy=proxy, timeout=timeout)
           ^^^^^^^^^^^^^^^^^^^^^^^^^^^^^^^^^^^^^^^^^^^^^^^^^^^^^^^^^^^^^^^^^^^^^^^^^^^^^^^^^^^^^^^^^^^^^^^^^^^^^^^^^^^^^^^^^^^^^^^^^^^^^^^^^^^^^^^^^^^^^^^
  File "C:\Users\Manas\AppData\Roaming\Python\Python311\site-packages\yfinance\utils.py", line 104, in wrapper
    result = func(*args, **kwargs)
             ^^^^^^^^^^^^^^^^^^^^^
  File "C:\Users\Manas\AppData\Roaming\Python\Python311\site-packages\yfinance\data.py", line 411, in _make_request
    raise YFRateLimitError()
yfinance.exceptions.YFRateLimitError: Too Many Requests. Rate limited. Try after a while.

During handling of the above exception, another exception occurred:

Traceback (most recent call last):
  File "E:\Stock\backend\python\risk_analysis.py", line 314, in risk_analysis_model
    data = get_stock_data(new_stock_ticker)
           ^^^^^^^^^^^^^^^^^^^^^^^^^^^^^^^^
  File "E:\Stock\backend\python\risk_analysis.py", line 73, in get_stock_data
    except yf.shared.exceptions.YFinanceError as yfe:
           ^^^^^^^^^^^^^^^^^^^^
AttributeError: module 'yfinance.shared' has no attribute 'exceptions'

2025-05-25 14:28:08,401 - root - INFO - Performing risk analysis for AAPL
2025-05-25 14:28:10,063 - root - ERROR - Error in risk analysis model for AAPL: module 'yfinance.shared' has no attribute 'exceptions'
2025-05-25 14:28:10,067 - root - ERROR - Traceback (most recent call last):
  File "E:\Stock\backend\python\risk_analysis.py", line 58, in get_stock_data
    hist = stock.history(period=period, interval=interval)
           ^^^^^^^^^^^^^^^^^^^^^^^^^^^^^^^^^^^^^^^^^^^^^^^
  File "C:\Users\Manas\AppData\Roaming\Python\Python311\site-packages\yfinance\utils.py", line 104, in wrapper
    result = func(*args, **kwargs)
             ^^^^^^^^^^^^^^^^^^^^^
  File "C:\Users\Manas\AppData\Roaming\Python\Python311\site-packages\yfinance\base.py", line 82, in history
    return self._lazy_load_price_history().history(*args, **kwargs)
           ^^^^^^^^^^^^^^^^^^^^^^^^^^^^^^^^^^^^^^^^^^^^^^^^^^^^^^^^
  File "C:\Users\Manas\AppData\Roaming\Python\Python311\site-packages\yfinance\utils.py", line 104, in wrapper
    result = func(*args, **kwargs)
             ^^^^^^^^^^^^^^^^^^^^^
  File "C:\Users\Manas\AppData\Roaming\Python\Python311\site-packages\yfinance\scrapers\history.py", line 175, in history
    data = get_fn(
           ^^^^^^^
  File "C:\Users\Manas\AppData\Roaming\Python\Python311\site-packages\yfinance\utils.py", line 104, in wrapper
    result = func(*args, **kwargs)
             ^^^^^^^^^^^^^^^^^^^^^
  File "C:\Users\Manas\AppData\Roaming\Python\Python311\site-packages\yfinance\data.py", line 349, in get
    return self._make_request(url, request_method = self._session.get, user_agent_headers=user_agent_headers, params=params, proxy=proxy, timeout=timeout)
           ^^^^^^^^^^^^^^^^^^^^^^^^^^^^^^^^^^^^^^^^^^^^^^^^^^^^^^^^^^^^^^^^^^^^^^^^^^^^^^^^^^^^^^^^^^^^^^^^^^^^^^^^^^^^^^^^^^^^^^^^^^^^^^^^^^^^^^^^^^^^^^^
  File "C:\Users\Manas\AppData\Roaming\Python\Python311\site-packages\yfinance\utils.py", line 104, in wrapper
    result = func(*args, **kwargs)
             ^^^^^^^^^^^^^^^^^^^^^
  File "C:\Users\Manas\AppData\Roaming\Python\Python311\site-packages\yfinance\data.py", line 411, in _make_request
    raise YFRateLimitError()
yfinance.exceptions.YFRateLimitError: Too Many Requests. Rate limited. Try after a while.

During handling of the above exception, another exception occurred:

Traceback (most recent call last):
  File "E:\Stock\backend\python\risk_analysis.py", line 314, in risk_analysis_model
    data = get_stock_data(new_stock_ticker)
           ^^^^^^^^^^^^^^^^^^^^^^^^^^^^^^^^
  File "E:\Stock\backend\python\risk_analysis.py", line 73, in get_stock_data
    except yf.shared.exceptions.YFinanceError as yfe:
           ^^^^^^^^^^^^^^^^^^^^
AttributeError: module 'yfinance.shared' has no attribute 'exceptions'

2025-05-25 14:28:10,338 - root - INFO - Performing risk analysis for GOOGL
2025-05-25 14:28:11,761 - root - ERROR - Error in risk analysis model for GOOGL: module 'yfinance.shared' has no attribute 'exceptions'
2025-05-25 14:28:11,764 - root - ERROR - Traceback (most recent call last):
  File "E:\Stock\backend\python\risk_analysis.py", line 58, in get_stock_data
    hist = stock.history(period=period, interval=interval)
           ^^^^^^^^^^^^^^^^^^^^^^^^^^^^^^^^^^^^^^^^^^^^^^^
  File "C:\Users\Manas\AppData\Roaming\Python\Python311\site-packages\yfinance\utils.py", line 104, in wrapper
    result = func(*args, **kwargs)
             ^^^^^^^^^^^^^^^^^^^^^
  File "C:\Users\Manas\AppData\Roaming\Python\Python311\site-packages\yfinance\base.py", line 82, in history
    return self._lazy_load_price_history().history(*args, **kwargs)
           ^^^^^^^^^^^^^^^^^^^^^^^^^^^^^^^^^^^^^^^^^^^^^^^^^^^^^^^^
  File "C:\Users\Manas\AppData\Roaming\Python\Python311\site-packages\yfinance\utils.py", line 104, in wrapper
    result = func(*args, **kwargs)
             ^^^^^^^^^^^^^^^^^^^^^
  File "C:\Users\Manas\AppData\Roaming\Python\Python311\site-packages\yfinance\scrapers\history.py", line 175, in history
    data = get_fn(
           ^^^^^^^
  File "C:\Users\Manas\AppData\Roaming\Python\Python311\site-packages\yfinance\utils.py", line 104, in wrapper
    result = func(*args, **kwargs)
             ^^^^^^^^^^^^^^^^^^^^^
  File "C:\Users\Manas\AppData\Roaming\Python\Python311\site-packages\yfinance\data.py", line 349, in get
    return self._make_request(url, request_method = self._session.get, user_agent_headers=user_agent_headers, params=params, proxy=proxy, timeout=timeout)
           ^^^^^^^^^^^^^^^^^^^^^^^^^^^^^^^^^^^^^^^^^^^^^^^^^^^^^^^^^^^^^^^^^^^^^^^^^^^^^^^^^^^^^^^^^^^^^^^^^^^^^^^^^^^^^^^^^^^^^^^^^^^^^^^^^^^^^^^^^^^^^^^
  File "C:\Users\Manas\AppData\Roaming\Python\Python311\site-packages\yfinance\utils.py", line 104, in wrapper
    result = func(*args, **kwargs)
             ^^^^^^^^^^^^^^^^^^^^^
  File "C:\Users\Manas\AppData\Roaming\Python\Python311\site-packages\yfinance\data.py", line 411, in _make_request
    raise YFRateLimitError()
yfinance.exceptions.YFRateLimitError: Too Many Requests. Rate limited. Try after a while.

During handling of the above exception, another exception occurred:

Traceback (most recent call last):
  File "E:\Stock\backend\python\risk_analysis.py", line 314, in risk_analysis_model
    data = get_stock_data(new_stock_ticker)
           ^^^^^^^^^^^^^^^^^^^^^^^^^^^^^^^^
  File "E:\Stock\backend\python\risk_analysis.py", line 73, in get_stock_data
    except yf.shared.exceptions.YFinanceError as yfe:
           ^^^^^^^^^^^^^^^^^^^^
AttributeError: module 'yfinance.shared' has no attribute 'exceptions'

2025-05-25 14:28:14,676 - root - INFO - Performing risk analysis for TSLA
2025-05-25 14:28:16,446 - root - ERROR - Error in risk analysis model for TSLA: module 'yfinance.shared' has no attribute 'exceptions'
2025-05-25 14:28:16,450 - root - ERROR - Traceback (most recent call last):
  File "E:\Stock\backend\python\risk_analysis.py", line 58, in get_stock_data
    hist = stock.history(period=period, interval=interval)
           ^^^^^^^^^^^^^^^^^^^^^^^^^^^^^^^^^^^^^^^^^^^^^^^
  File "C:\Users\Manas\AppData\Roaming\Python\Python311\site-packages\yfinance\utils.py", line 104, in wrapper
    result = func(*args, **kwargs)
             ^^^^^^^^^^^^^^^^^^^^^
  File "C:\Users\Manas\AppData\Roaming\Python\Python311\site-packages\yfinance\base.py", line 82, in history
    return self._lazy_load_price_history().history(*args, **kwargs)
           ^^^^^^^^^^^^^^^^^^^^^^^^^^^^^^^^^^^^^^^^^^^^^^^^^^^^^^^^
  File "C:\Users\Manas\AppData\Roaming\Python\Python311\site-packages\yfinance\utils.py", line 104, in wrapper
    result = func(*args, **kwargs)
             ^^^^^^^^^^^^^^^^^^^^^
  File "C:\Users\Manas\AppData\Roaming\Python\Python311\site-packages\yfinance\scrapers\history.py", line 175, in history
    data = get_fn(
           ^^^^^^^
  File "C:\Users\Manas\AppData\Roaming\Python\Python311\site-packages\yfinance\utils.py", line 104, in wrapper
    result = func(*args, **kwargs)
             ^^^^^^^^^^^^^^^^^^^^^
  File "C:\Users\Manas\AppData\Roaming\Python\Python311\site-packages\yfinance\data.py", line 349, in get
    return self._make_request(url, request_method = self._session.get, user_agent_headers=user_agent_headers, params=params, proxy=proxy, timeout=timeout)
           ^^^^^^^^^^^^^^^^^^^^^^^^^^^^^^^^^^^^^^^^^^^^^^^^^^^^^^^^^^^^^^^^^^^^^^^^^^^^^^^^^^^^^^^^^^^^^^^^^^^^^^^^^^^^^^^^^^^^^^^^^^^^^^^^^^^^^^^^^^^^^^^
  File "C:\Users\Manas\AppData\Roaming\Python\Python311\site-packages\yfinance\utils.py", line 104, in wrapper
    result = func(*args, **kwargs)
             ^^^^^^^^^^^^^^^^^^^^^
  File "C:\Users\Manas\AppData\Roaming\Python\Python311\site-packages\yfinance\data.py", line 411, in _make_request
    raise YFRateLimitError()
yfinance.exceptions.YFRateLimitError: Too Many Requests. Rate limited. Try after a while.

During handling of the above exception, another exception occurred:

Traceback (most recent call last):
  File "E:\Stock\backend\python\risk_analysis.py", line 314, in risk_analysis_model
    data = get_stock_data(new_stock_ticker)
           ^^^^^^^^^^^^^^^^^^^^^^^^^^^^^^^^
  File "E:\Stock\backend\python\risk_analysis.py", line 73, in get_stock_data
    except yf.shared.exceptions.YFinanceError as yfe:
           ^^^^^^^^^^^^^^^^^^^^
AttributeError: module 'yfinance.shared' has no attribute 'exceptions'

2025-05-25 14:28:21,336 - root - INFO - Performing risk analysis for META
2025-05-25 14:28:29,841 - root - INFO - Model for META trained and saved with accuracy: 0.9200
2025-05-25 14:28:35,870 - root - INFO - Performing risk analysis for NFLX
2025-05-25 14:28:38,281 - root - ERROR - Error in risk analysis model for NFLX: module 'yfinance.shared' has no attribute 'exceptions'
2025-05-25 14:28:38,292 - root - ERROR - Traceback (most recent call last):
  File "E:\Stock\backend\python\risk_analysis.py", line 58, in get_stock_data
    hist = stock.history(period=period, interval=interval)
           ^^^^^^^^^^^^^^^^^^^^^^^^^^^^^^^^^^^^^^^^^^^^^^^
  File "C:\Users\Manas\AppData\Roaming\Python\Python311\site-packages\yfinance\utils.py", line 104, in wrapper
    result = func(*args, **kwargs)
             ^^^^^^^^^^^^^^^^^^^^^
  File "C:\Users\Manas\AppData\Roaming\Python\Python311\site-packages\yfinance\base.py", line 82, in history
    return self._lazy_load_price_history().history(*args, **kwargs)
           ^^^^^^^^^^^^^^^^^^^^^^^^^^^^^^^^^^^^^^^^^^^^^^^^^^^^^^^^
  File "C:\Users\Manas\AppData\Roaming\Python\Python311\site-packages\yfinance\utils.py", line 104, in wrapper
    result = func(*args, **kwargs)
             ^^^^^^^^^^^^^^^^^^^^^
  File "C:\Users\Manas\AppData\Roaming\Python\Python311\site-packages\yfinance\scrapers\history.py", line 175, in history
    data = get_fn(
           ^^^^^^^
  File "C:\Users\Manas\AppData\Roaming\Python\Python311\site-packages\yfinance\utils.py", line 104, in wrapper
    result = func(*args, **kwargs)
             ^^^^^^^^^^^^^^^^^^^^^
  File "C:\Users\Manas\AppData\Roaming\Python\Python311\site-packages\yfinance\data.py", line 349, in get
    return self._make_request(url, request_method = self._session.get, user_agent_headers=user_agent_headers, params=params, proxy=proxy, timeout=timeout)
           ^^^^^^^^^^^^^^^^^^^^^^^^^^^^^^^^^^^^^^^^^^^^^^^^^^^^^^^^^^^^^^^^^^^^^^^^^^^^^^^^^^^^^^^^^^^^^^^^^^^^^^^^^^^^^^^^^^^^^^^^^^^^^^^^^^^^^^^^^^^^^^^
  File "C:\Users\Manas\AppData\Roaming\Python\Python311\site-packages\yfinance\utils.py", line 104, in wrapper
    result = func(*args, **kwargs)
             ^^^^^^^^^^^^^^^^^^^^^
  File "C:\Users\Manas\AppData\Roaming\Python\Python311\site-packages\yfinance\data.py", line 411, in _make_request
    raise YFRateLimitError()
yfinance.exceptions.YFRateLimitError: Too Many Requests. Rate limited. Try after a while.

During handling of the above exception, another exception occurred:

Traceback (most recent call last):
  File "E:\Stock\backend\python\risk_analysis.py", line 314, in risk_analysis_model
    data = get_stock_data(new_stock_ticker)
           ^^^^^^^^^^^^^^^^^^^^^^^^^^^^^^^^
  File "E:\Stock\backend\python\risk_analysis.py", line 73, in get_stock_data
    except yf.shared.exceptions.YFinanceError as yfe:
           ^^^^^^^^^^^^^^^^^^^^
AttributeError: module 'yfinance.shared' has no attribute 'exceptions'

2025-05-25 14:28:42,582 - root - INFO - Performing risk analysis for MSFT
2025-05-25 14:28:51,346 - root - INFO - Model for MSFT trained and saved with accuracy: 0.8418
2025-05-25 14:28:57,960 - root - INFO - Performing risk analysis for NVDA
2025-05-25 14:28:59,561 - root - ERROR - Error in risk analysis model for NVDA: module 'yfinance.shared' has no attribute 'exceptions'
2025-05-25 14:28:59,565 - root - ERROR - Traceback (most recent call last):
  File "E:\Stock\backend\python\risk_analysis.py", line 58, in get_stock_data
    hist = stock.history(period=period, interval=interval)
           ^^^^^^^^^^^^^^^^^^^^^^^^^^^^^^^^^^^^^^^^^^^^^^^
  File "C:\Users\Manas\AppData\Roaming\Python\Python311\site-packages\yfinance\utils.py", line 104, in wrapper
    result = func(*args, **kwargs)
             ^^^^^^^^^^^^^^^^^^^^^
  File "C:\Users\Manas\AppData\Roaming\Python\Python311\site-packages\yfinance\base.py", line 82, in history
    return self._lazy_load_price_history().history(*args, **kwargs)
           ^^^^^^^^^^^^^^^^^^^^^^^^^^^^^^^^^^^^^^^^^^^^^^^^^^^^^^^^
  File "C:\Users\Manas\AppData\Roaming\Python\Python311\site-packages\yfinance\utils.py", line 104, in wrapper
    result = func(*args, **kwargs)
             ^^^^^^^^^^^^^^^^^^^^^
  File "C:\Users\Manas\AppData\Roaming\Python\Python311\site-packages\yfinance\scrapers\history.py", line 175, in history
    data = get_fn(
           ^^^^^^^
  File "C:\Users\Manas\AppData\Roaming\Python\Python311\site-packages\yfinance\utils.py", line 104, in wrapper
    result = func(*args, **kwargs)
             ^^^^^^^^^^^^^^^^^^^^^
  File "C:\Users\Manas\AppData\Roaming\Python\Python311\site-packages\yfinance\data.py", line 349, in get
    return self._make_request(url, request_method = self._session.get, user_agent_headers=user_agent_headers, params=params, proxy=proxy, timeout=timeout)
           ^^^^^^^^^^^^^^^^^^^^^^^^^^^^^^^^^^^^^^^^^^^^^^^^^^^^^^^^^^^^^^^^^^^^^^^^^^^^^^^^^^^^^^^^^^^^^^^^^^^^^^^^^^^^^^^^^^^^^^^^^^^^^^^^^^^^^^^^^^^^^^^
  File "C:\Users\Manas\AppData\Roaming\Python\Python311\site-packages\yfinance\utils.py", line 104, in wrapper
    result = func(*args, **kwargs)
             ^^^^^^^^^^^^^^^^^^^^^
  File "C:\Users\Manas\AppData\Roaming\Python\Python311\site-packages\yfinance\data.py", line 411, in _make_request
    raise YFRateLimitError()
yfinance.exceptions.YFRateLimitError: Too Many Requests. Rate limited. Try after a while.

During handling of the above exception, another exception occurred:

Traceback (most recent call last):
  File "E:\Stock\backend\python\risk_analysis.py", line 314, in risk_analysis_model
    data = get_stock_data(new_stock_ticker)
           ^^^^^^^^^^^^^^^^^^^^^^^^^^^^^^^^
  File "E:\Stock\backend\python\risk_analysis.py", line 73, in get_stock_data
    except yf.shared.exceptions.YFinanceError as yfe:
           ^^^^^^^^^^^^^^^^^^^^
AttributeError: module 'yfinance.shared' has no attribute 'exceptions'

2025-05-25 14:29:08,872 - root - INFO - Performing risk analysis for ZOMATO.BO
2025-05-25 14:29:17,510 - root - INFO - Model for ZOMATO.BO trained and saved with accuracy: 0.9356
2025-05-25 16:09:34,573 - root - INFO - Performing risk analysis for AAPL
2025-05-25 16:09:36,939 - root - ERROR - Error in risk analysis model for AAPL: module 'yfinance.shared' has no attribute 'exceptions'
2025-05-25 16:09:36,954 - root - ERROR - Traceback (most recent call last):
  File "E:\Stock\backend\python\risk_analysis.py", line 58, in get_stock_data
    hist = stock.history(period=period, interval=interval)
           ^^^^^^^^^^^^^^^^^^^^^^^^^^^^^^^^^^^^^^^^^^^^^^^
  File "C:\Users\Manas\AppData\Roaming\Python\Python311\site-packages\yfinance\utils.py", line 104, in wrapper
    result = func(*args, **kwargs)
             ^^^^^^^^^^^^^^^^^^^^^
  File "C:\Users\Manas\AppData\Roaming\Python\Python311\site-packages\yfinance\base.py", line 82, in history
    return self._lazy_load_price_history().history(*args, **kwargs)
           ^^^^^^^^^^^^^^^^^^^^^^^^^^^^^^^^^^^^^^^^^^^^^^^^^^^^^^^^
  File "C:\Users\Manas\AppData\Roaming\Python\Python311\site-packages\yfinance\utils.py", line 104, in wrapper
    result = func(*args, **kwargs)
             ^^^^^^^^^^^^^^^^^^^^^
  File "C:\Users\Manas\AppData\Roaming\Python\Python311\site-packages\yfinance\scrapers\history.py", line 175, in history
    data = get_fn(
           ^^^^^^^
  File "C:\Users\Manas\AppData\Roaming\Python\Python311\site-packages\yfinance\utils.py", line 104, in wrapper
    result = func(*args, **kwargs)
             ^^^^^^^^^^^^^^^^^^^^^
  File "C:\Users\Manas\AppData\Roaming\Python\Python311\site-packages\yfinance\data.py", line 349, in get
    return self._make_request(url, request_method = self._session.get, user_agent_headers=user_agent_headers, params=params, proxy=proxy, timeout=timeout)
           ^^^^^^^^^^^^^^^^^^^^^^^^^^^^^^^^^^^^^^^^^^^^^^^^^^^^^^^^^^^^^^^^^^^^^^^^^^^^^^^^^^^^^^^^^^^^^^^^^^^^^^^^^^^^^^^^^^^^^^^^^^^^^^^^^^^^^^^^^^^^^^^
  File "C:\Users\Manas\AppData\Roaming\Python\Python311\site-packages\yfinance\utils.py", line 104, in wrapper
    result = func(*args, **kwargs)
             ^^^^^^^^^^^^^^^^^^^^^
  File "C:\Users\Manas\AppData\Roaming\Python\Python311\site-packages\yfinance\data.py", line 411, in _make_request
    raise YFRateLimitError()
yfinance.exceptions.YFRateLimitError: Too Many Requests. Rate limited. Try after a while.

During handling of the above exception, another exception occurred:

Traceback (most recent call last):
  File "E:\Stock\backend\python\risk_analysis.py", line 314, in risk_analysis_model
    data = get_stock_data(new_stock_ticker)
           ^^^^^^^^^^^^^^^^^^^^^^^^^^^^^^^^
  File "E:\Stock\backend\python\risk_analysis.py", line 73, in get_stock_data
    except yf.shared.exceptions.YFinanceError as yfe:
           ^^^^^^^^^^^^^^^^^^^^
AttributeError: module 'yfinance.shared' has no attribute 'exceptions'

2025-05-25 16:09:44,468 - root - INFO - Performing risk analysis for AAPL
2025-05-25 16:09:47,299 - root - ERROR - Error in risk analysis model for AAPL: module 'yfinance.shared' has no attribute 'exceptions'
2025-05-25 16:09:47,308 - root - ERROR - Traceback (most recent call last):
  File "E:\Stock\backend\python\risk_analysis.py", line 58, in get_stock_data
    hist = stock.history(period=period, interval=interval)
           ^^^^^^^^^^^^^^^^^^^^^^^^^^^^^^^^^^^^^^^^^^^^^^^
  File "C:\Users\Manas\AppData\Roaming\Python\Python311\site-packages\yfinance\utils.py", line 104, in wrapper
    result = func(*args, **kwargs)
             ^^^^^^^^^^^^^^^^^^^^^
  File "C:\Users\Manas\AppData\Roaming\Python\Python311\site-packages\yfinance\base.py", line 82, in history
    return self._lazy_load_price_history().history(*args, **kwargs)
           ^^^^^^^^^^^^^^^^^^^^^^^^^^^^^^^^^^^^^^^^^^^^^^^^^^^^^^^^
  File "C:\Users\Manas\AppData\Roaming\Python\Python311\site-packages\yfinance\utils.py", line 104, in wrapper
    result = func(*args, **kwargs)
             ^^^^^^^^^^^^^^^^^^^^^
  File "C:\Users\Manas\AppData\Roaming\Python\Python311\site-packages\yfinance\scrapers\history.py", line 175, in history
    data = get_fn(
           ^^^^^^^
  File "C:\Users\Manas\AppData\Roaming\Python\Python311\site-packages\yfinance\utils.py", line 104, in wrapper
    result = func(*args, **kwargs)
             ^^^^^^^^^^^^^^^^^^^^^
  File "C:\Users\Manas\AppData\Roaming\Python\Python311\site-packages\yfinance\data.py", line 349, in get
    return self._make_request(url, request_method = self._session.get, user_agent_headers=user_agent_headers, params=params, proxy=proxy, timeout=timeout)
           ^^^^^^^^^^^^^^^^^^^^^^^^^^^^^^^^^^^^^^^^^^^^^^^^^^^^^^^^^^^^^^^^^^^^^^^^^^^^^^^^^^^^^^^^^^^^^^^^^^^^^^^^^^^^^^^^^^^^^^^^^^^^^^^^^^^^^^^^^^^^^^^
  File "C:\Users\Manas\AppData\Roaming\Python\Python311\site-packages\yfinance\utils.py", line 104, in wrapper
    result = func(*args, **kwargs)
             ^^^^^^^^^^^^^^^^^^^^^
  File "C:\Users\Manas\AppData\Roaming\Python\Python311\site-packages\yfinance\data.py", line 411, in _make_request
    raise YFRateLimitError()
yfinance.exceptions.YFRateLimitError: Too Many Requests. Rate limited. Try after a while.

During handling of the above exception, another exception occurred:

Traceback (most recent call last):
  File "E:\Stock\backend\python\risk_analysis.py", line 314, in risk_analysis_model
    data = get_stock_data(new_stock_ticker)
           ^^^^^^^^^^^^^^^^^^^^^^^^^^^^^^^^
  File "E:\Stock\backend\python\risk_analysis.py", line 73, in get_stock_data
    except yf.shared.exceptions.YFinanceError as yfe:
           ^^^^^^^^^^^^^^^^^^^^
AttributeError: module 'yfinance.shared' has no attribute 'exceptions'

2025-05-25 16:09:49,319 - root - INFO - Performing risk analysis for MSFT
2025-05-25 16:09:52,131 - root - ERROR - Error in risk analysis model for MSFT: module 'yfinance.shared' has no attribute 'exceptions'
2025-05-25 16:09:52,145 - root - ERROR - Traceback (most recent call last):
  File "E:\Stock\backend\python\risk_analysis.py", line 58, in get_stock_data
    hist = stock.history(period=period, interval=interval)
           ^^^^^^^^^^^^^^^^^^^^^^^^^^^^^^^^^^^^^^^^^^^^^^^
  File "C:\Users\Manas\AppData\Roaming\Python\Python311\site-packages\yfinance\utils.py", line 104, in wrapper
    result = func(*args, **kwargs)
             ^^^^^^^^^^^^^^^^^^^^^
  File "C:\Users\Manas\AppData\Roaming\Python\Python311\site-packages\yfinance\base.py", line 82, in history
    return self._lazy_load_price_history().history(*args, **kwargs)
           ^^^^^^^^^^^^^^^^^^^^^^^^^^^^^^^^^^^^^^^^^^^^^^^^^^^^^^^^
  File "C:\Users\Manas\AppData\Roaming\Python\Python311\site-packages\yfinance\utils.py", line 104, in wrapper
    result = func(*args, **kwargs)
             ^^^^^^^^^^^^^^^^^^^^^
  File "C:\Users\Manas\AppData\Roaming\Python\Python311\site-packages\yfinance\scrapers\history.py", line 175, in history
    data = get_fn(
           ^^^^^^^
  File "C:\Users\Manas\AppData\Roaming\Python\Python311\site-packages\yfinance\utils.py", line 104, in wrapper
    result = func(*args, **kwargs)
             ^^^^^^^^^^^^^^^^^^^^^
  File "C:\Users\Manas\AppData\Roaming\Python\Python311\site-packages\yfinance\data.py", line 349, in get
    return self._make_request(url, request_method = self._session.get, user_agent_headers=user_agent_headers, params=params, proxy=proxy, timeout=timeout)
           ^^^^^^^^^^^^^^^^^^^^^^^^^^^^^^^^^^^^^^^^^^^^^^^^^^^^^^^^^^^^^^^^^^^^^^^^^^^^^^^^^^^^^^^^^^^^^^^^^^^^^^^^^^^^^^^^^^^^^^^^^^^^^^^^^^^^^^^^^^^^^^^
  File "C:\Users\Manas\AppData\Roaming\Python\Python311\site-packages\yfinance\utils.py", line 104, in wrapper
    result = func(*args, **kwargs)
             ^^^^^^^^^^^^^^^^^^^^^
  File "C:\Users\Manas\AppData\Roaming\Python\Python311\site-packages\yfinance\data.py", line 411, in _make_request
    raise YFRateLimitError()
yfinance.exceptions.YFRateLimitError: Too Many Requests. Rate limited. Try after a while.

During handling of the above exception, another exception occurred:

Traceback (most recent call last):
  File "E:\Stock\backend\python\risk_analysis.py", line 314, in risk_analysis_model
    data = get_stock_data(new_stock_ticker)
           ^^^^^^^^^^^^^^^^^^^^^^^^^^^^^^^^
  File "E:\Stock\backend\python\risk_analysis.py", line 73, in get_stock_data
    except yf.shared.exceptions.YFinanceError as yfe:
           ^^^^^^^^^^^^^^^^^^^^
AttributeError: module 'yfinance.shared' has no attribute 'exceptions'

2025-05-25 16:09:57,824 - root - INFO - Performing risk analysis for AMZN
2025-05-25 16:10:01,938 - root - INFO - Performing risk analysis for GOOGL
2025-05-25 16:10:04,238 - root - ERROR - Error in risk analysis model for GOOGL: module 'yfinance.shared' has no attribute 'exceptions'
2025-05-25 16:10:04,252 - root - ERROR - Traceback (most recent call last):
  File "E:\Stock\backend\python\risk_analysis.py", line 58, in get_stock_data
    hist = stock.history(period=period, interval=interval)
           ^^^^^^^^^^^^^^^^^^^^^^^^^^^^^^^^^^^^^^^^^^^^^^^
  File "C:\Users\Manas\AppData\Roaming\Python\Python311\site-packages\yfinance\utils.py", line 104, in wrapper
    result = func(*args, **kwargs)
             ^^^^^^^^^^^^^^^^^^^^^
  File "C:\Users\Manas\AppData\Roaming\Python\Python311\site-packages\yfinance\base.py", line 82, in history
    return self._lazy_load_price_history().history(*args, **kwargs)
           ^^^^^^^^^^^^^^^^^^^^^^^^^^^^^^^^^^^^^^^^^^^^^^^^^^^^^^^^
  File "C:\Users\Manas\AppData\Roaming\Python\Python311\site-packages\yfinance\utils.py", line 104, in wrapper
    result = func(*args, **kwargs)
             ^^^^^^^^^^^^^^^^^^^^^
  File "C:\Users\Manas\AppData\Roaming\Python\Python311\site-packages\yfinance\scrapers\history.py", line 175, in history
    data = get_fn(
           ^^^^^^^
  File "C:\Users\Manas\AppData\Roaming\Python\Python311\site-packages\yfinance\utils.py", line 104, in wrapper
    result = func(*args, **kwargs)
             ^^^^^^^^^^^^^^^^^^^^^
  File "C:\Users\Manas\AppData\Roaming\Python\Python311\site-packages\yfinance\data.py", line 349, in get
    return self._make_request(url, request_method = self._session.get, user_agent_headers=user_agent_headers, params=params, proxy=proxy, timeout=timeout)
           ^^^^^^^^^^^^^^^^^^^^^^^^^^^^^^^^^^^^^^^^^^^^^^^^^^^^^^^^^^^^^^^^^^^^^^^^^^^^^^^^^^^^^^^^^^^^^^^^^^^^^^^^^^^^^^^^^^^^^^^^^^^^^^^^^^^^^^^^^^^^^^^
  File "C:\Users\Manas\AppData\Roaming\Python\Python311\site-packages\yfinance\utils.py", line 104, in wrapper
    result = func(*args, **kwargs)
             ^^^^^^^^^^^^^^^^^^^^^
  File "C:\Users\Manas\AppData\Roaming\Python\Python311\site-packages\yfinance\data.py", line 411, in _make_request
    raise YFRateLimitError()
yfinance.exceptions.YFRateLimitError: Too Many Requests. Rate limited. Try after a while.

During handling of the above exception, another exception occurred:

Traceback (most recent call last):
  File "E:\Stock\backend\python\risk_analysis.py", line 314, in risk_analysis_model
    data = get_stock_data(new_stock_ticker)
           ^^^^^^^^^^^^^^^^^^^^^^^^^^^^^^^^
  File "E:\Stock\backend\python\risk_analysis.py", line 73, in get_stock_data
    except yf.shared.exceptions.YFinanceError as yfe:
           ^^^^^^^^^^^^^^^^^^^^
AttributeError: module 'yfinance.shared' has no attribute 'exceptions'

2025-05-25 16:10:15,816 - root - INFO - Performing risk analysis for NFLX
2025-05-25 16:10:18,189 - root - ERROR - Error in risk analysis model for NFLX: module 'yfinance.shared' has no attribute 'exceptions'
2025-05-25 16:10:18,203 - root - ERROR - Traceback (most recent call last):
  File "E:\Stock\backend\python\risk_analysis.py", line 58, in get_stock_data
    hist = stock.history(period=period, interval=interval)
           ^^^^^^^^^^^^^^^^^^^^^^^^^^^^^^^^^^^^^^^^^^^^^^^
  File "C:\Users\Manas\AppData\Roaming\Python\Python311\site-packages\yfinance\utils.py", line 104, in wrapper
    result = func(*args, **kwargs)
             ^^^^^^^^^^^^^^^^^^^^^
  File "C:\Users\Manas\AppData\Roaming\Python\Python311\site-packages\yfinance\base.py", line 82, in history
    return self._lazy_load_price_history().history(*args, **kwargs)
           ^^^^^^^^^^^^^^^^^^^^^^^^^^^^^^^^^^^^^^^^^^^^^^^^^^^^^^^^
  File "C:\Users\Manas\AppData\Roaming\Python\Python311\site-packages\yfinance\utils.py", line 104, in wrapper
    result = func(*args, **kwargs)
             ^^^^^^^^^^^^^^^^^^^^^
  File "C:\Users\Manas\AppData\Roaming\Python\Python311\site-packages\yfinance\scrapers\history.py", line 175, in history
    data = get_fn(
           ^^^^^^^
  File "C:\Users\Manas\AppData\Roaming\Python\Python311\site-packages\yfinance\utils.py", line 104, in wrapper
    result = func(*args, **kwargs)
             ^^^^^^^^^^^^^^^^^^^^^
  File "C:\Users\Manas\AppData\Roaming\Python\Python311\site-packages\yfinance\data.py", line 349, in get
    return self._make_request(url, request_method = self._session.get, user_agent_headers=user_agent_headers, params=params, proxy=proxy, timeout=timeout)
           ^^^^^^^^^^^^^^^^^^^^^^^^^^^^^^^^^^^^^^^^^^^^^^^^^^^^^^^^^^^^^^^^^^^^^^^^^^^^^^^^^^^^^^^^^^^^^^^^^^^^^^^^^^^^^^^^^^^^^^^^^^^^^^^^^^^^^^^^^^^^^^^
  File "C:\Users\Manas\AppData\Roaming\Python\Python311\site-packages\yfinance\utils.py", line 104, in wrapper
    result = func(*args, **kwargs)
             ^^^^^^^^^^^^^^^^^^^^^
  File "C:\Users\Manas\AppData\Roaming\Python\Python311\site-packages\yfinance\data.py", line 411, in _make_request
    raise YFRateLimitError()
yfinance.exceptions.YFRateLimitError: Too Many Requests. Rate limited. Try after a while.

During handling of the above exception, another exception occurred:

Traceback (most recent call last):
  File "E:\Stock\backend\python\risk_analysis.py", line 314, in risk_analysis_model
    data = get_stock_data(new_stock_ticker)
           ^^^^^^^^^^^^^^^^^^^^^^^^^^^^^^^^
  File "E:\Stock\backend\python\risk_analysis.py", line 73, in get_stock_data
    except yf.shared.exceptions.YFinanceError as yfe:
           ^^^^^^^^^^^^^^^^^^^^
AttributeError: module 'yfinance.shared' has no attribute 'exceptions'

2025-05-25 16:10:28,231 - root - INFO - Performing risk analysis for GOOGL
2025-05-25 16:10:30,122 - root - ERROR - Error in risk analysis model for GOOGL: module 'yfinance.shared' has no attribute 'exceptions'
2025-05-25 16:10:30,136 - root - ERROR - Traceback (most recent call last):
  File "E:\Stock\backend\python\risk_analysis.py", line 58, in get_stock_data
    hist = stock.history(period=period, interval=interval)
           ^^^^^^^^^^^^^^^^^^^^^^^^^^^^^^^^^^^^^^^^^^^^^^^
  File "C:\Users\Manas\AppData\Roaming\Python\Python311\site-packages\yfinance\utils.py", line 104, in wrapper
    result = func(*args, **kwargs)
             ^^^^^^^^^^^^^^^^^^^^^
  File "C:\Users\Manas\AppData\Roaming\Python\Python311\site-packages\yfinance\base.py", line 82, in history
    return self._lazy_load_price_history().history(*args, **kwargs)
           ^^^^^^^^^^^^^^^^^^^^^^^^^^^^^^^^^^^^^^^^^^^^^^^^^^^^^^^^
  File "C:\Users\Manas\AppData\Roaming\Python\Python311\site-packages\yfinance\utils.py", line 104, in wrapper
    result = func(*args, **kwargs)
             ^^^^^^^^^^^^^^^^^^^^^
  File "C:\Users\Manas\AppData\Roaming\Python\Python311\site-packages\yfinance\scrapers\history.py", line 175, in history
    data = get_fn(
           ^^^^^^^
  File "C:\Users\Manas\AppData\Roaming\Python\Python311\site-packages\yfinance\utils.py", line 104, in wrapper
    result = func(*args, **kwargs)
             ^^^^^^^^^^^^^^^^^^^^^
  File "C:\Users\Manas\AppData\Roaming\Python\Python311\site-packages\yfinance\data.py", line 349, in get
    return self._make_request(url, request_method = self._session.get, user_agent_headers=user_agent_headers, params=params, proxy=proxy, timeout=timeout)
           ^^^^^^^^^^^^^^^^^^^^^^^^^^^^^^^^^^^^^^^^^^^^^^^^^^^^^^^^^^^^^^^^^^^^^^^^^^^^^^^^^^^^^^^^^^^^^^^^^^^^^^^^^^^^^^^^^^^^^^^^^^^^^^^^^^^^^^^^^^^^^^^
  File "C:\Users\Manas\AppData\Roaming\Python\Python311\site-packages\yfinance\utils.py", line 104, in wrapper
    result = func(*args, **kwargs)
             ^^^^^^^^^^^^^^^^^^^^^
  File "C:\Users\Manas\AppData\Roaming\Python\Python311\site-packages\yfinance\data.py", line 411, in _make_request
    raise YFRateLimitError()
yfinance.exceptions.YFRateLimitError: Too Many Requests. Rate limited. Try after a while.

During handling of the above exception, another exception occurred:

Traceback (most recent call last):
  File "E:\Stock\backend\python\risk_analysis.py", line 314, in risk_analysis_model
    data = get_stock_data(new_stock_ticker)
           ^^^^^^^^^^^^^^^^^^^^^^^^^^^^^^^^
  File "E:\Stock\backend\python\risk_analysis.py", line 73, in get_stock_data
    except yf.shared.exceptions.YFinanceError as yfe:
           ^^^^^^^^^^^^^^^^^^^^
AttributeError: module 'yfinance.shared' has no attribute 'exceptions'

2025-05-25 16:10:40,950 - root - INFO - Performing risk analysis for META
2025-05-25 16:10:42,692 - root - ERROR - Error in risk analysis model for META: module 'yfinance.shared' has no attribute 'exceptions'
2025-05-25 16:10:42,698 - root - ERROR - Traceback (most recent call last):
  File "E:\Stock\backend\python\risk_analysis.py", line 58, in get_stock_data
    hist = stock.history(period=period, interval=interval)
           ^^^^^^^^^^^^^^^^^^^^^^^^^^^^^^^^^^^^^^^^^^^^^^^
  File "C:\Users\Manas\AppData\Roaming\Python\Python311\site-packages\yfinance\utils.py", line 104, in wrapper
    result = func(*args, **kwargs)
             ^^^^^^^^^^^^^^^^^^^^^
  File "C:\Users\Manas\AppData\Roaming\Python\Python311\site-packages\yfinance\base.py", line 82, in history
    return self._lazy_load_price_history().history(*args, **kwargs)
           ^^^^^^^^^^^^^^^^^^^^^^^^^^^^^^^^^^^^^^^^^^^^^^^^^^^^^^^^
  File "C:\Users\Manas\AppData\Roaming\Python\Python311\site-packages\yfinance\utils.py", line 104, in wrapper
    result = func(*args, **kwargs)
             ^^^^^^^^^^^^^^^^^^^^^
  File "C:\Users\Manas\AppData\Roaming\Python\Python311\site-packages\yfinance\scrapers\history.py", line 175, in history
    data = get_fn(
           ^^^^^^^
  File "C:\Users\Manas\AppData\Roaming\Python\Python311\site-packages\yfinance\utils.py", line 104, in wrapper
    result = func(*args, **kwargs)
             ^^^^^^^^^^^^^^^^^^^^^
  File "C:\Users\Manas\AppData\Roaming\Python\Python311\site-packages\yfinance\data.py", line 349, in get
    return self._make_request(url, request_method = self._session.get, user_agent_headers=user_agent_headers, params=params, proxy=proxy, timeout=timeout)
           ^^^^^^^^^^^^^^^^^^^^^^^^^^^^^^^^^^^^^^^^^^^^^^^^^^^^^^^^^^^^^^^^^^^^^^^^^^^^^^^^^^^^^^^^^^^^^^^^^^^^^^^^^^^^^^^^^^^^^^^^^^^^^^^^^^^^^^^^^^^^^^^
  File "C:\Users\Manas\AppData\Roaming\Python\Python311\site-packages\yfinance\utils.py", line 104, in wrapper
    result = func(*args, **kwargs)
             ^^^^^^^^^^^^^^^^^^^^^
  File "C:\Users\Manas\AppData\Roaming\Python\Python311\site-packages\yfinance\data.py", line 411, in _make_request
    raise YFRateLimitError()
yfinance.exceptions.YFRateLimitError: Too Many Requests. Rate limited. Try after a while.

During handling of the above exception, another exception occurred:

Traceback (most recent call last):
  File "E:\Stock\backend\python\risk_analysis.py", line 314, in risk_analysis_model
    data = get_stock_data(new_stock_ticker)
           ^^^^^^^^^^^^^^^^^^^^^^^^^^^^^^^^
  File "E:\Stock\backend\python\risk_analysis.py", line 73, in get_stock_data
    except yf.shared.exceptions.YFinanceError as yfe:
           ^^^^^^^^^^^^^^^^^^^^
AttributeError: module 'yfinance.shared' has no attribute 'exceptions'

2025-05-25 16:10:54,083 - root - INFO - Performing risk analysis for TSLA
2025-05-25 16:10:56,274 - root - ERROR - Error in risk analysis model for TSLA: module 'yfinance.shared' has no attribute 'exceptions'
2025-05-25 16:10:56,289 - root - ERROR - Traceback (most recent call last):
  File "E:\Stock\backend\python\risk_analysis.py", line 58, in get_stock_data
    hist = stock.history(period=period, interval=interval)
           ^^^^^^^^^^^^^^^^^^^^^^^^^^^^^^^^^^^^^^^^^^^^^^^
  File "C:\Users\Manas\AppData\Roaming\Python\Python311\site-packages\yfinance\utils.py", line 104, in wrapper
    result = func(*args, **kwargs)
             ^^^^^^^^^^^^^^^^^^^^^
  File "C:\Users\Manas\AppData\Roaming\Python\Python311\site-packages\yfinance\base.py", line 82, in history
    return self._lazy_load_price_history().history(*args, **kwargs)
           ^^^^^^^^^^^^^^^^^^^^^^^^^^^^^^^^^^^^^^^^^^^^^^^^^^^^^^^^
  File "C:\Users\Manas\AppData\Roaming\Python\Python311\site-packages\yfinance\utils.py", line 104, in wrapper
    result = func(*args, **kwargs)
             ^^^^^^^^^^^^^^^^^^^^^
  File "C:\Users\Manas\AppData\Roaming\Python\Python311\site-packages\yfinance\scrapers\history.py", line 175, in history
    data = get_fn(
           ^^^^^^^
  File "C:\Users\Manas\AppData\Roaming\Python\Python311\site-packages\yfinance\utils.py", line 104, in wrapper
    result = func(*args, **kwargs)
             ^^^^^^^^^^^^^^^^^^^^^
  File "C:\Users\Manas\AppData\Roaming\Python\Python311\site-packages\yfinance\data.py", line 349, in get
    return self._make_request(url, request_method = self._session.get, user_agent_headers=user_agent_headers, params=params, proxy=proxy, timeout=timeout)
           ^^^^^^^^^^^^^^^^^^^^^^^^^^^^^^^^^^^^^^^^^^^^^^^^^^^^^^^^^^^^^^^^^^^^^^^^^^^^^^^^^^^^^^^^^^^^^^^^^^^^^^^^^^^^^^^^^^^^^^^^^^^^^^^^^^^^^^^^^^^^^^^
  File "C:\Users\Manas\AppData\Roaming\Python\Python311\site-packages\yfinance\utils.py", line 104, in wrapper
    result = func(*args, **kwargs)
             ^^^^^^^^^^^^^^^^^^^^^
  File "C:\Users\Manas\AppData\Roaming\Python\Python311\site-packages\yfinance\data.py", line 411, in _make_request
    raise YFRateLimitError()
yfinance.exceptions.YFRateLimitError: Too Many Requests. Rate limited. Try after a while.

During handling of the above exception, another exception occurred:

Traceback (most recent call last):
  File "E:\Stock\backend\python\risk_analysis.py", line 314, in risk_analysis_model
    data = get_stock_data(new_stock_ticker)
           ^^^^^^^^^^^^^^^^^^^^^^^^^^^^^^^^
  File "E:\Stock\backend\python\risk_analysis.py", line 73, in get_stock_data
    except yf.shared.exceptions.YFinanceError as yfe:
           ^^^^^^^^^^^^^^^^^^^^
AttributeError: module 'yfinance.shared' has no attribute 'exceptions'

2025-05-25 16:11:06,840 - root - INFO - Performing risk analysis for NVDA
2025-05-25 16:11:08,974 - root - ERROR - Error in risk analysis model for NVDA: module 'yfinance.shared' has no attribute 'exceptions'
2025-05-25 16:11:08,988 - root - ERROR - Traceback (most recent call last):
  File "E:\Stock\backend\python\risk_analysis.py", line 58, in get_stock_data
    hist = stock.history(period=period, interval=interval)
           ^^^^^^^^^^^^^^^^^^^^^^^^^^^^^^^^^^^^^^^^^^^^^^^
  File "C:\Users\Manas\AppData\Roaming\Python\Python311\site-packages\yfinance\utils.py", line 104, in wrapper
    result = func(*args, **kwargs)
             ^^^^^^^^^^^^^^^^^^^^^
  File "C:\Users\Manas\AppData\Roaming\Python\Python311\site-packages\yfinance\base.py", line 82, in history
    return self._lazy_load_price_history().history(*args, **kwargs)
           ^^^^^^^^^^^^^^^^^^^^^^^^^^^^^^^^^^^^^^^^^^^^^^^^^^^^^^^^
  File "C:\Users\Manas\AppData\Roaming\Python\Python311\site-packages\yfinance\utils.py", line 104, in wrapper
    result = func(*args, **kwargs)
             ^^^^^^^^^^^^^^^^^^^^^
  File "C:\Users\Manas\AppData\Roaming\Python\Python311\site-packages\yfinance\scrapers\history.py", line 175, in history
    data = get_fn(
           ^^^^^^^
  File "C:\Users\Manas\AppData\Roaming\Python\Python311\site-packages\yfinance\utils.py", line 104, in wrapper
    result = func(*args, **kwargs)
             ^^^^^^^^^^^^^^^^^^^^^
  File "C:\Users\Manas\AppData\Roaming\Python\Python311\site-packages\yfinance\data.py", line 349, in get
    return self._make_request(url, request_method = self._session.get, user_agent_headers=user_agent_headers, params=params, proxy=proxy, timeout=timeout)
           ^^^^^^^^^^^^^^^^^^^^^^^^^^^^^^^^^^^^^^^^^^^^^^^^^^^^^^^^^^^^^^^^^^^^^^^^^^^^^^^^^^^^^^^^^^^^^^^^^^^^^^^^^^^^^^^^^^^^^^^^^^^^^^^^^^^^^^^^^^^^^^^
  File "C:\Users\Manas\AppData\Roaming\Python\Python311\site-packages\yfinance\utils.py", line 104, in wrapper
    result = func(*args, **kwargs)
             ^^^^^^^^^^^^^^^^^^^^^
  File "C:\Users\Manas\AppData\Roaming\Python\Python311\site-packages\yfinance\data.py", line 411, in _make_request
    raise YFRateLimitError()
yfinance.exceptions.YFRateLimitError: Too Many Requests. Rate limited. Try after a while.

During handling of the above exception, another exception occurred:

Traceback (most recent call last):
  File "E:\Stock\backend\python\risk_analysis.py", line 314, in risk_analysis_model
    data = get_stock_data(new_stock_ticker)
           ^^^^^^^^^^^^^^^^^^^^^^^^^^^^^^^^
  File "E:\Stock\backend\python\risk_analysis.py", line 73, in get_stock_data
    except yf.shared.exceptions.YFinanceError as yfe:
           ^^^^^^^^^^^^^^^^^^^^
AttributeError: module 'yfinance.shared' has no attribute 'exceptions'

2025-05-25 16:11:21,044 - root - INFO - Performing risk analysis for GOOGL
2025-05-25 16:11:23,350 - root - ERROR - Error in risk analysis model for GOOGL: module 'yfinance.shared' has no attribute 'exceptions'
2025-05-25 16:11:23,357 - root - ERROR - Traceback (most recent call last):
  File "E:\Stock\backend\python\risk_analysis.py", line 58, in get_stock_data
    hist = stock.history(period=period, interval=interval)
           ^^^^^^^^^^^^^^^^^^^^^^^^^^^^^^^^^^^^^^^^^^^^^^^
  File "C:\Users\Manas\AppData\Roaming\Python\Python311\site-packages\yfinance\utils.py", line 104, in wrapper
    result = func(*args, **kwargs)
             ^^^^^^^^^^^^^^^^^^^^^
  File "C:\Users\Manas\AppData\Roaming\Python\Python311\site-packages\yfinance\base.py", line 82, in history
    return self._lazy_load_price_history().history(*args, **kwargs)
           ^^^^^^^^^^^^^^^^^^^^^^^^^^^^^^^^^^^^^^^^^^^^^^^^^^^^^^^^
  File "C:\Users\Manas\AppData\Roaming\Python\Python311\site-packages\yfinance\utils.py", line 104, in wrapper
    result = func(*args, **kwargs)
             ^^^^^^^^^^^^^^^^^^^^^
  File "C:\Users\Manas\AppData\Roaming\Python\Python311\site-packages\yfinance\scrapers\history.py", line 175, in history
    data = get_fn(
           ^^^^^^^
  File "C:\Users\Manas\AppData\Roaming\Python\Python311\site-packages\yfinance\utils.py", line 104, in wrapper
    result = func(*args, **kwargs)
             ^^^^^^^^^^^^^^^^^^^^^
  File "C:\Users\Manas\AppData\Roaming\Python\Python311\site-packages\yfinance\data.py", line 349, in get
    return self._make_request(url, request_method = self._session.get, user_agent_headers=user_agent_headers, params=params, proxy=proxy, timeout=timeout)
           ^^^^^^^^^^^^^^^^^^^^^^^^^^^^^^^^^^^^^^^^^^^^^^^^^^^^^^^^^^^^^^^^^^^^^^^^^^^^^^^^^^^^^^^^^^^^^^^^^^^^^^^^^^^^^^^^^^^^^^^^^^^^^^^^^^^^^^^^^^^^^^^
  File "C:\Users\Manas\AppData\Roaming\Python\Python311\site-packages\yfinance\utils.py", line 104, in wrapper
    result = func(*args, **kwargs)
             ^^^^^^^^^^^^^^^^^^^^^
  File "C:\Users\Manas\AppData\Roaming\Python\Python311\site-packages\yfinance\data.py", line 411, in _make_request
    raise YFRateLimitError()
yfinance.exceptions.YFRateLimitError: Too Many Requests. Rate limited. Try after a while.

During handling of the above exception, another exception occurred:

Traceback (most recent call last):
  File "E:\Stock\backend\python\risk_analysis.py", line 314, in risk_analysis_model
    data = get_stock_data(new_stock_ticker)
           ^^^^^^^^^^^^^^^^^^^^^^^^^^^^^^^^
  File "E:\Stock\backend\python\risk_analysis.py", line 73, in get_stock_data
    except yf.shared.exceptions.YFinanceError as yfe:
           ^^^^^^^^^^^^^^^^^^^^
AttributeError: module 'yfinance.shared' has no attribute 'exceptions'

2025-05-25 16:11:36,915 - root - INFO - Performing risk analysis for AMZN
